Workbook

Sheet alle Dateien
A1: Pfad | B1: Bohrung | C1: Dateiname | D1: Dateityp
A2: P:\I2535F001_KI-Explore\Bohrprotokolle_Schichtenverzeichnisse\Allmenhausen_10_1960 | B2: Allmenhausen_10_1960 | C2: 1960-2850.pdf | D2: =IF(ISNUMBER(SEARCH(".pdf",C2)),"pdf",IF(ISNUMBER(SEARCH(".tif",C2)),"tif",IF(ISNUMBER(SEARCH(".las",C2)),"las",IF(ISNUMBER(SEARCH(".sdg",C2)),"sdg",IF(ISNUMBER(SEARCH(".xlsx",C2)),"xlsx",IF(ISNUMBER(SEARCH(".docx",C2)),"docx",IF(ISNUMBER(SEARCH(".rhistory",C2)),"rhistory",IF(ISNUMBER(SEARCH(".db",C2)),"db",IF(ISNUMBER(SEARCH(".jpg",C2)),"jpg",IF(ISNUMBER(SEARCH(".png",C2)),"png",IF(ISNUMBER(SEARCH(".mdb",C2)),"mdb",IF(ISNUMBER(SEARCH(".xml",C2)),"xml",IF(ISNUMBER(SEARCH(".xls",C2)),"xls",IF(ISNUMBER(SEARCH(".txt",C2)),"txt",IF(ISNUMBER(SEARCH(".tsf",C2)),"tsf",IF(ISNUMBER(SEARCH(".sch",C2)),"sch","ZIP oder R")))))))))))))))) -> pdf
A3: P:\I2535F001_KI-Explore\Bohrprotokolle_Schichtenverzeichnisse\Allmenhausen_10_1960 | B3: Allmenhausen_10_1960 | C3: 617195_E_Allmenhausen_10_1961_Bohrjournal.pdf | D3: =IF(ISNUMBER(SEARCH(".pdf",C3)),"pdf",IF(ISNUMBER(SEARCH(".tif",C3)),"tif",IF(ISNUMBER(SEARCH(".las",C3)),"las",IF(ISNUMBER(SEARCH(".sdg",C3)),"sdg",IF(ISNUMBER(SEARCH(".xlsx",C3)),"xlsx",IF(ISNUMBER(SEARCH(".docx",C3)),"docx",IF(ISNUMBER(SEARCH(".rhistory",C3)),"rhistory",IF(ISNUMBER(SEARCH(".db",C3)),"db",IF(ISNUMBER(SEARCH(".jpg",C3)),"jpg",IF(ISNUMBER(SEARCH(".png",C3)),"png",IF(ISNUMBER(SEARCH(".mdb",C3)),"mdb",IF(ISNUMBER(SEARCH(".xml",C3)),"xml",IF(ISNUMBER(SEARCH(".xls",C3)),"xls",IF(ISNUMBER(SEARCH(".txt",C3)),"txt",IF(ISNUMBER(SEARCH(".tsf",C3)),"tsf",IF(ISNUMBER(SEARCH(".sch",C3)),"sch","ZIP oder R")))))))))))))))) -> pdf
A4: P:\I2535F001_KI-Explore\Bohrprotokolle_Schichtenverzeichnisse\Allmenhausen_10_1960 | B4: Allmenhausen_10_1960 | C4: 617195_E_Allmenhausen_10_1961_Geophysik_01.TIF | D4: =IF(ISNUMBER(SEARCH(".pdf",C4)),"pdf",IF(ISNUMBER(SEARCH(".tif",C4)),"tif",IF(ISNUMBER(SEARCH(".las",C4)),"las",IF(ISNUMBER(SEARCH(".sdg",C4)),"sdg",IF(ISNUMBER(SEARCH(".xlsx",C4)),"xlsx",IF(ISNUMBER(SEARCH(".docx",C4)),"docx",IF(ISNUMBER(SEARCH(".rhistory",C4)),"rhistory",IF(ISNUMBER(SEARCH(".db",C4)),"db",IF(ISNUMBER(SEARCH(".jpg",C4)),"jpg",IF(ISNUMBER(SEARCH(".png",C4)),"png",IF(ISNUMBER(SEARCH(".mdb",C4)),"mdb",IF(ISNUMBER(SEARCH(".xml",C4)),"xml",IF(ISNUMBER(SEARCH(".xls",C4)),"xls",IF(ISNUMBER(SEARCH(".txt",C4)),"txt",IF(ISNUMBER(SEARCH(".tsf",C4)),"tsf",IF(ISNUMBER(SEARCH(".sch",C4)),"sch","ZIP oder R")))))))))))))))) -> tif
A5: P:\I2535F001_KI-Explore\Bohrprotokolle_Schichtenverzeichnisse\Allmenhausen_10_1960 | B5: Allmenhausen_10_1960 | C5: 617195_E_Allmenhausen_10_1961_Geophysik_02.TIF | D5: =IF(ISNUMBER(SEARCH(".pdf",C5)),"pdf",IF(ISNUMBER(SEARCH(".tif",C5)),"tif",IF(ISNUMBER(SEARCH(".las",C5)),"las",IF(ISNUMBER(SEARCH(".sdg",C5)),"sdg",IF(ISNUMBER(SEARCH(".xlsx",C5)),"xlsx",IF(ISNUMBER(SEARCH(".docx",C5)),"docx",IF(ISNUMBER(SEARCH(".rhistory",C5)),"rhistory",IF(ISNUMBER(SEARCH(".db",C5)),"db",IF(ISNUMBER(SEARCH(".jpg",C5)),"jpg",IF(ISNUMBER(SEARCH(".png",C5)),"png",IF(ISNUMBER(SEARCH(".mdb",C5)),"mdb",IF(ISNUMBER(SEARCH(".xml",C5)),"xml",IF(ISNUMBER(SEARCH(".xls",C5)),"xls",IF(ISNUMBER(SEARCH(".txt",C5)),"txt",IF(ISNUMBER(SEARCH(".tsf",C5)),"tsf",IF(ISNUMBER(SEARCH(".sch",C5)),"sch","ZIP oder R")))))))))))))))) -> tif
A6: P:\I2535F001_KI-Explore\Bohrprotokolle_Schichtenverzeichnisse\Allmenhausen_10_1960 | B6: Allmenhausen_10_1960 | C6: 617195_E_Allmenhausen_10_1961_Geophysik_03.TIF | D6: =IF(ISNUMBER(SEARCH(".pdf",C6)),"pdf",IF(ISNUMBER(SEARCH(".tif",C6)),"tif",IF(ISNUMBER(SEARCH(".las",C6)),"las",IF(ISNUMBER(SEARCH(".sdg",C6)),"sdg",IF(ISNUMBER(SEARCH(".xlsx",C6)),"xlsx",IF(ISNUMBER(SEARCH(".docx",C6)),"docx",IF(ISNUMBER(SEARCH(".rhistory",C6)),"rhistory",IF(ISNUMBER(SEARCH(".db",C6)),"db",IF(ISNUMBER(SEARCH(".jpg",C6)),"jpg",IF(ISNUMBER(SEARCH(".png",C6)),"png",IF(ISNUMBER(SEARCH(".mdb",C6)),"mdb",IF(ISNUMBER(SEARCH(".xml",C6)),"xml",IF(ISNUMBER(SEARCH(".xls",C6)),"xls",IF(ISNUMBER(SEARCH(".txt",C6)),"txt",IF(ISNUMBER(SEARCH(".tsf",C6)),"tsf",IF(ISNUMBER(SEARCH(".sch",C6)),"sch","ZIP oder R")))))))))))))))) -> tif
A7: P:\I2535F001_KI-Explore\Bohrprotokolle_Schichtenverzeichnisse\Allmenhausen_10_1960 | B7: Allmenhausen_10_1960 | C7: 617195_E_Allmenhausen_10_1961_Geophysik_04.TIF | D7: =IF(ISNUMBER(SEARCH(".pdf",C7)),"pdf",IF(ISNUMBER(SEARCH(".tif",C7)),"tif",IF(ISNUMBER(SEARCH(".las",C7)),"las",IF(ISNUMBER(SEARCH(".sdg",C7)),"sdg",IF(ISNUMBER(SEARCH(".xlsx",C7)),"xlsx",IF(ISNUMBER(SEARCH(".docx",C7)),"docx",IF(ISNUMBER(SEARCH(".rhistory",C7)),"rhistory",IF(ISNUMBER(SEARCH(".db",C7)),"db",IF(ISNUMBER(SEARCH(".jpg",C7)),"jpg",IF(ISNUMBER(SEARCH(".png",C7)),"png",IF(ISNUMBER(SEARCH(".mdb",C7)),"mdb",IF(ISNUMBER(SEARCH(".xml",C7)),"xml",IF(ISNUMBER(SEARCH(".xls",C7)),"xls",IF(ISNUMBER(SEARCH(".txt",C7)),"txt",IF(ISNUMBER(SEARCH(".tsf",C7)),"tsf",IF(ISNUMBER(SEARCH(".sch",C7)),"sch","ZIP oder R")))))))))))))))) -> tif
A8: P:\I2535F001_KI-Explore\Bohrprotokolle_Schichtenverzeichnisse\Allmenhausen_11_1960 | B8: Allmenhausen_11_1960 | C8: Allmenhausen_11_SVZ.pdf | D8: =IF(ISNUMBER(SEARCH(".pdf",C8)),"pdf",IF(ISNUMBER(SEARCH(".tif",C8)),"tif",IF(ISNUMBER(SEARCH(".las",C8)),"las",IF(ISNUMBER(SEARCH(".sdg",C8)),"sdg",IF(ISNUMBER(SEARCH(".xlsx",C8)),"xlsx",IF(ISNUMBER(SEARCH(".docx",C8)),"docx",IF(ISNUMBER(SEARCH(".rhistory",C8)),"rhistory",IF(ISNUMBER(SEARCH(".db",C8)),"db",IF(ISNUMBER(SEARCH(".jpg",C8)),"jpg",IF(ISNUMBER(SEARCH(".png",C8)),"png",IF(ISNUMBER(SEARCH(".mdb",C8)),"mdb",IF(ISNUMBER(SEARCH(".xml",C8)),"xml",IF(ISNUMBER(SEARCH(".xls",C8)),"xls",IF(ISNUMBER(SEARCH(".txt",C8)),"txt",IF(ISNUMBER(SEARCH(".tsf",C8)),"tsf",IF(ISNUMBER(SEARCH(".sch",C8)),"sch","ZIP oder R")))))))))))))))) -> pdf
A9: P:\I2535F001_KI-Explore\Bohrprotokolle_Schichtenverzeichnisse\Allmenhausen_2_1959 | B9: Allmenhausen_2_1959 | C9: 1959-2690.pdf | D9: =IF(ISNUMBER(SEARCH(".pdf",C9)),"pdf",IF(ISNUMBER(SEARCH(".tif",C9)),"tif",IF(ISNUMBER(SEARCH(".las",C9)),"las",IF(ISNUMBER(SEARCH(".sdg",C9)),"sdg",IF(ISNUMBER(SEARCH(".xlsx",C9)),"xlsx",IF(ISNUMBER(SEARCH(".docx",C9)),"docx",IF(ISNUMBER(SEARCH(".rhistory",C9)),"rhistory",IF(ISNUMBER(SEARCH(".db",C9)),"db",IF(ISNUMBER(SEARCH(".jpg",C9)),"jpg",IF(ISNUMBER(SEARCH(".png",C9)),"png",IF(ISNUMBER(SEARCH(".mdb",C9)),"mdb",IF(ISNUMBER(SEARCH(".xml",C9)),"xml",IF(ISNUMBER(SEARCH(".xls",C9)),"xls",IF(ISNUMBER(SEARCH(".txt",C9)),"txt",IF(ISNUMBER(SEARCH(".tsf",C9)),"tsf",IF(ISNUMBER(SEARCH(".sch",C9)),"sch","ZIP oder R")))))))))))))))) -> pdf
A10: P:\I2535F001_KI-Explore\Bohrprotokolle_Schichtenverzeichnisse\Allmenhausen_32_1968 | B10: Allmenhausen_32_1968 | C10: Allmenhausen_32_1968_Log.pdf | D10: =IF(ISNUMBER(SEARCH(".pdf",C10)),"pdf",IF(ISNUMBER(SEARCH(".tif",C10)),"tif",IF(ISNUMBER(SEARCH(".las",C10)),"las",IF(ISNUMBER(SEARCH(".sdg",C10)),"sdg",IF(ISNUMBER(SEARCH(".xlsx",C10)),"xlsx",IF(ISNUMBER(SEARCH(".docx",C10)),"docx",IF(ISNUMBER(SEARCH(".rhistory",C10)),"rhistory",IF(ISNUMBER(SEARCH(".db",C10)),"db",IF(ISNUMBER(SEARCH(".jpg",C10)),"jpg",IF(ISNUMBER(SEARCH(".png",C10)),"png",IF(ISNUMBER(SEARCH(".mdb",C10)),"mdb",IF(ISNUMBER(SEARCH(".xml",C10)),"xml",IF(ISNUMBER(SEARCH(".xls",C10)),"xls",IF(ISNUMBER(SEARCH(".txt",C10)),"txt",IF(ISNUMBER(SEARCH(".tsf",C10)),"tsf",IF(ISNUMBER(SEARCH(".sch",C10)),"sch","ZIP oder R")))))))))))))))) -> pdf
A11: P:\I2535F001_KI-Explore\Bohrprotokolle_Schichtenverzeichnisse\Allmenhausen_32_1968 | B11: Allmenhausen_32_1968 | C11: Allmenhausen_32_1968_SVZ.pdf | D11: =IF(ISNUMBER(SEARCH(".pdf",C11)),"pdf",IF(ISNUMBER(SEARCH(".tif",C11)),"tif",IF(ISNUMBER(SEARCH(".las",C11)),"las",IF(ISNUMBER(SEARCH(".sdg",C11)),"sdg",IF(ISNUMBER(SEARCH(".xlsx",C11)),"xlsx",IF(ISNUMBER(SEARCH(".docx",C11)),"docx",IF(ISNUMBER(SEARCH(".rhistory",C11)),"rhistory",IF(ISNUMBER(SEARCH(".db",C11)),"db",IF(ISNUMBER(SEARCH(".jpg",C11)),"jpg",IF(ISNUMBER(SEARCH(".png",C11)),"png",IF(ISNUMBER(SEARCH(".mdb",C11)),"mdb",IF(ISNUMBER(SEARCH(".xml",C11)),"xml",IF(ISNUMBER(SEARCH(".xls",C11)),"xls",IF(ISNUMBER(SEARCH(".txt",C11)),"txt",IF(ISNUMBER(SEARCH(".tsf",C11)),"tsf",IF(ISNUMBER(SEARCH(".sch",C11)),"sch","ZIP oder R")))))))))))))))) -> pdf
A12: P:\I2535F001_KI-Explore\Bohrprotokolle_Schichtenverzeichnisse\Allmenhausen_33_1968 | B12: Allmenhausen_33_1968 | C12: 1968-2913.pdf | D12: =IF(ISNUMBER(SEARCH(".pdf",C12)),"pdf",IF(ISNUMBER(SEARCH(".tif",C12)),"tif",IF(ISNUMBER(SEARCH(".las",C12)),"las",IF(ISNUMBER(SEARCH(".sdg",C12)),"sdg",IF(ISNUMBER(SEARCH(".xlsx",C12)),"xlsx",IF(ISNUMBER(SEARCH(".docx",C12)),"docx",IF(ISNUMBER(SEARCH(".rhistory",C12)),"rhistory",IF(ISNUMBER(SEARCH(".db",C12)),"db",IF(ISNUMBER(SEARCH(".jpg",C12)),"jpg",IF(ISNUMBER(SEARCH(".png",C12)),"png",IF(ISNUMBER(SEARCH(".mdb",C12)),"mdb",IF(ISNUMBER(SEARCH(".xml",C12)),"xml",IF(ISNUMBER(SEARCH(".xls",C12)),"xls",IF(ISNUMBER(SEARCH(".txt",C12)),"txt",IF(ISNUMBER(SEARCH(".tsf",C12)),"tsf",IF(ISNUMBER(SEARCH(".sch",C12)),"sch","ZIP oder R")))))))))))))))) -> pdf
A13: P:\I2535F001_KI-Explore\Bohrprotokolle_Schichtenverzeichnisse\Allmenhausen_33_1968 | B13: Allmenhausen_33_1968 | C13: Allmenhausen_33_168_Log.pdf | D13: =IF(ISNUMBER(SEARCH(".pdf",C13)),"pdf",IF(ISNUMBER(SEARCH(".tif",C13)),"tif",IF(ISNUMBER(SEARCH(".las",C13)),"las",IF(ISNUMBER(SEARCH(".sdg",C13)),"sdg",IF(ISNUMBER(SEARCH(".xlsx",C13)),"xlsx",IF(ISNUMBER(SEARCH(".docx",C13)),"docx",IF(ISNUMBER(SEARCH(".rhistory",C13)),"rhistory",IF(ISNUMBER(SEARCH(".db",C13)),"db",IF(ISNUMBER(SEARCH(".jpg",C13)),"jpg",IF(ISNUMBER(SEARCH(".png",C13)),"png",IF(ISNUMBER(SEARCH(".mdb",C13)),"mdb",IF(ISNUMBER(SEARCH(".xml",C13)),"xml",IF(ISNUMBER(SEARCH(".xls",C13)),"xls",IF(ISNUMBER(SEARCH(".txt",C13)),"txt",IF(ISNUMBER(SEARCH(".tsf",C13)),"tsf",IF(ISNUMBER(SEARCH(".sch",C13)),"sch","ZIP oder R")))))))))))))))) -> pdf
... A929: P:\I2535F001_KI-Explore\Bohrprotokolle_Schichtenverzeichnisse\K-UTEC_neu | B929: K-UTEC_neu | C929: TLUBN.zip | D929: =IF(ISNUMBER(SEARCH(".pdf",C929)),"pdf",IF(ISNUMBER(SEARCH(".tif",C929)),"tif",IF(ISNUMBER(SEARCH(".las",C929)),"las",IF(ISNUMBER(SEARCH(".sdg",C929)),"sdg",IF(ISNUMBER(SEARCH(".xlsx",C929)),"xlsx",IF(ISNUMBER(SEARCH(".docx",C929)),"docx",IF(ISNUMBER(SEARCH(".rhistory",C929)),"rhistory",IF(ISNUMBER(SEARCH(".db",C929)),"db",IF(ISNUMBER(SEARCH(".jpg",C929)),"jpg",IF(ISNUMBER(SEARCH(".png",C929)),"png",IF(ISNUMBER(SEARCH(".mdb",C929)),"mdb",IF(ISNUMBER(SEARCH(".xml",C929)),"xml",IF(ISNUMBER(SEARCH(".xls",C929)),"xls",IF(ISNUMBER(SEARCH(".txt",C929)),"txt",IF(ISNUMBER(SEARCH(".tsf",C929)),"tsf",IF(ISNUMBER(SEARCH(".sch",C929)),"sch","ZIP oder R")))))))))))))))) -> ZIP oder R
A930: P:\I2535F001_KI-Explore\Bohrprotokolle_Schichtenverzeichnisse\K-UTEC_neu\TLUBN\anfrage_2025_02_k-utec | C930: anfrage_250206_gt_k-utec.accdb | D930: =IF(ISNUMBER(SEARCH(".pdf",C930)),"pdf",IF(ISNUMBER(SEARCH(".tif",C930)),"tif",IF(ISNUMBER(SEARCH(".las",C930)),"las",IF(ISNUMBER(SEARCH(".sdg",C930)),"sdg",IF(ISNUMBER(SEARCH(".xlsx",C930)),"xlsx",IF(ISNUMBER(SEARCH(".docx",C930)),"docx",IF(ISNUMBER(SEARCH(".rhistory",C930)),"rhistory",IF(ISNUMBER(SEARCH(".db",C930)),"db",IF(ISNUMBER(SEARCH(".jpg",C930)),"jpg",IF(ISNUMBER(SEARCH(".png",C930)),"png",IF(ISNUMBER(SEARCH(".mdb",C930)),"mdb",IF(ISNUMBER(SEARCH(".xml",C930)),"xml",IF(ISNUMBER(SEARCH(".xls",C930)),"xls",IF(ISNUMBER(SEARCH(".txt",C930)),"txt",IF(ISNUMBER(SEARCH(".tsf",C930)),"tsf",IF(ISNUMBER(SEARCH(".sch",C930)),"sch","ZIP oder R")))))))))))))))) -> ZIP oder R
A931: P:\I2535F001_KI-Explore\Bohrprotokolle_Schichtenverzeichnisse\K-UTEC_neu\TLUBN\anfrage_2025_02_k-utec | C931: Dokumente_FIS_gewässer.xlsx | D931: =IF(ISNUMBER(SEARCH(".pdf",C931)),"pdf",IF(ISNUMBER(SEARCH(".tif",C931)),"tif",IF(ISNUMBER(SEARCH(".las",C931)),"las",IF(ISNUMBER(SEARCH(".sdg",C931)),"sdg",IF(ISNUMBER(SEARCH(".xlsx",C931)),"xlsx",IF(ISNUMBER(SEARCH(".docx",C931)),"docx",IF(ISNUMBER(SEARCH(".rhistory",C931)),"rhistory",IF(ISNUMBER(SEARCH(".db",C931)),"db",IF(ISNUMBER(SEARCH(".jpg",C931)),"jpg",IF(ISNUMBER(SEARCH(".png",C931)),"png",IF(ISNUMBER(SEARCH(".mdb",C931)),"mdb",IF(ISNUMBER(SEARCH(".xml",C931)),"xml",IF(ISNUMBER(SEARCH(".xls",C931)),"xls",IF(ISNUMBER(SEARCH(".txt",C931)),"txt",IF(ISNUMBER(SEARCH(".tsf",C931)),"tsf",IF(ISNUMBER(SEARCH(".sch",C931)),"sch","ZIP oder R")))))))))))))))) -> xlsx
A932: P:\I2535F001_KI-Explore\Bohrprotokolle_Schichtenverzeichnisse\K-UTEC_neu\TLUBN\anfrage_2025_02_k-utec\Aufschlussdokumente\108071 | B932: Straussfurt_T2_1963 | C932: 108071_E_Straussfurt_T2_1963.zip | D932: =IF(ISNUMBER(SEARCH(".pdf",C932)),"pdf",IF(ISNUMBER(SEARCH(".tif",C932)),"tif",IF(ISNUMBER(SEARCH(".las",C932)),"las",IF(ISNUMBER(SEARCH(".sdg",C932)),"sdg",IF(ISNUMBER(SEARCH(".xlsx",C932)),"xlsx",IF(ISNUMBER(SEARCH(".docx",C932)),"docx",IF(ISNUMBER(SEARCH(".rhistory",C932)),"rhistory",IF(ISNUMBER(SEARCH(".db",C932)),"db",IF(ISNUMBER(SEARCH(".jpg",C932)),"jpg",IF(ISNUMBER(SEARCH(".png",C932)),"png",IF(ISNUMBER(SEARCH(".mdb",C932)),"mdb",IF(ISNUMBER(SEARCH(".xml",C932)),"xml",IF(ISNUMBER(SEARCH(".xls",C932)),"xls",IF(ISNUMBER(SEARCH(".txt",C932)),"txt",IF(ISNUMBER(SEARCH(".tsf",C932)),"tsf",IF(ISNUMBER(SEARCH(".sch",C932)),"sch","ZIP oder R")))))))))))))))) -> ZIP oder R
A933: P:\I2535F001_KI-Explore\Bohrprotokolle_Schichtenverzeichnisse\K-UTEC_neu\TLUBN\anfrage_2025_02_k-utec\Aufschlussdokumente\108071 | B933: Straussfurt_T2_1963 | C933: 108071_E_Straussfurt_T2_1963_BLM.pdf | D933: =IF(ISNUMBER(SEARCH(".pdf",C933)),"pdf",IF(ISNUMBER(SEARCH(".tif",C933)),"tif",IF(ISNUMBER(SEARCH(".las",C933)),"las",IF(ISNUMBER(SEARCH(".sdg",C933)),"sdg",IF(ISNUMBER(SEARCH(".xlsx",C933)),"xlsx",IF(ISNUMBER(SEARCH(".docx",C933)),"docx",IF(ISNUMBER(SEARCH(".rhistory",C933)),"rhistory",IF(ISNUMBER(SEARCH(".db",C933)),"db",IF(ISNUMBER(SEARCH(".jpg",C933)),"jpg",IF(ISNUMBER(SEARCH(".png",C933)),"png",IF(ISNUMBER(SEARCH(".mdb",C933)),"mdb",IF(ISNUMBER(SEARCH(".xml",C933)),"xml",IF(ISNUMBER(SEARCH(".xls",C933)),"xls",IF(ISNUMBER(SEARCH(".txt",C933)),"txt",IF(ISNUMBER(SEARCH(".tsf",C933)),"tsf",IF(ISNUMBER(SEARCH(".sch",C933)),"sch","ZIP oder R")))))))))))))))) -> pdf
A934: P:\I2535F001_KI-Explore\Bohrprotokolle_Schichtenverzeichnisse\K-UTEC_neu\TLUBN\anfrage_2025_02_k-utec\Aufschlussdokumente\108071 | B934: Straussfurt_T2_1963 | C934: 108071_E_Straussfurt_T2_1963_Bohrjournal.pdf | D934: =IF(ISNUMBER(SEARCH(".pdf",C934)),"pdf",IF(ISNUMBER(SEARCH(".tif",C934)),"tif",IF(ISNUMBER(SEARCH(".las",C934)),"las",IF(ISNUMBER(SEARCH(".sdg",C934)),"sdg",IF(ISNUMBER(SEARCH(".xlsx",C934)),"xlsx",IF(ISNUMBER(SEARCH(".docx",C934)),"docx",IF(ISNUMBER(SEARCH(".rhistory",C934)),"rhistory",IF(ISNUMBER(SEARCH(".db",C934)),"db",IF(ISNUMBER(SEARCH(".jpg",C934)),"jpg",IF(ISNUMBER(SEARCH(".png",C934)),"png",IF(ISNUMBER(SEARCH(".mdb",C934)),"mdb",IF(ISNUMBER(SEARCH(".xml",C934)),"xml",IF(ISNUMBER(SEARCH(".xls",C934)),"xls",IF(ISNUMBER(SEARCH(".txt",C934)),"txt",IF(ISNUMBER(SEARCH(".tsf",C934)),"tsf",IF(ISNUMBER(SEARCH(".sch",C934)),"sch","ZIP oder R")))))))))))))))) -> pdf
A935: P:\I2535F001_KI-Explore\Bohrprotokolle_Schichtenverzeichnisse\K-UTEC_neu\TLUBN\anfrage_2025_02_k-utec\Aufschlussdokumente\108071 | B935: Straussfurt_T2_1963 | C935: 108071_E_Straußfurt_T2-1963_Kernmarschverzeichnis.pdf | D935: =IF(ISNUMBER(SEARCH(".pdf",C935)),"pdf",IF(ISNUMBER(SEARCH(".tif",C935)),"tif",IF(ISNUMBER(SEARCH(".las",C935)),"las",IF(ISNUMBER(SEARCH(".sdg",C935)),"sdg",IF(ISNUMBER(SEARCH(".xlsx",C935)),"xlsx",IF(ISNUMBER(SEARCH(".docx",C935)),"docx",IF(ISNUMBER(SEARCH(".rhistory",C935)),"rhistory",IF(ISNUMBER(SEARCH(".db",C935)),"db",IF(ISNUMBER(SEARCH(".jpg",C935)),"jpg",IF(ISNUMBER(SEARCH(".png",C935)),"png",IF(ISNUMBER(SEARCH(".mdb",C935)),"mdb",IF(ISNUMBER(SEARCH(".xml",C935)),"xml",IF(ISNUMBER(SEARCH(".xls",C935)),"xls",IF(ISNUMBER(SEARCH(".txt",C935)),"txt",IF(ISNUMBER(SEARCH(".tsf",C935)),"tsf",IF(ISNUMBER(SEARCH(".sch",C935)),"sch","ZIP oder R")))))))))))))))) -> pdf
A936: P:\I2535F001_KI-Explore\Bohrprotokolle_Schichtenverzeichnisse\K-UTEC_neu\TLUBN\anfrage_2025_02_k-utec\Aufschlussdokumente\108071\108071_E_Straussfurt_T2_1963 | B936: Straussfurt_T2_1963 | C936: 108071_E_Straussfurt_T2_1963_Composite_KORR.las | D936: =IF(ISNUMBER(SEARCH(".pdf",C936)),"pdf",IF(ISNUMBER(SEARCH(".tif",C936)),"tif",IF(ISNUMBER(SEARCH(".las",C936)),"las",IF(ISNUMBER(SEARCH(".sdg",C936)),"sdg",IF(ISNUMBER(SEARCH(".xlsx",C936)),"xlsx",IF(ISNUMBER(SEARCH(".docx",C936)),"docx",IF(ISNUMBER(SEARCH(".rhistory",C936)),"rhistory",IF(ISNUMBER(SEARCH(".db",C936)),"db",IF(ISNUMBER(SEARCH(".jpg",C936)),"jpg",IF(ISNUMBER(SEARCH(".png",C936)),"png",IF(ISNUMBER(SEARCH(".mdb",C936)),"mdb",IF(ISNUMBER(SEARCH(".xml",C936)),"xml",IF(ISNUMBER(SEARCH(".xls",C936)),"xls",IF(ISNUMBER(SEARCH(".txt",C936)),"txt",IF(ISNUMBER(SEARCH(".tsf",C936)),"tsf",IF(ISNUMBER(SEARCH(".sch",C936)),"sch","ZIP oder R")))))))))))))))) -> las
A937: P:\I2535F001_KI-Explore\Bohrprotokolle_Schichtenverzeichnisse\K-UTEC_neu\TLUBN\anfrage_2025_02_k-utec\Aufschlussdokumente\108071\108071_E_Straussfurt_T2_1963 | B937: Straussfurt_T2_1963 | C937: 108071_E_Straussfurt_T2_1963_Composite_SPEZ.las | D937: =IF(ISNUMBER(SEARCH(".pdf",C937)),"pdf",IF(ISNUMBER(SEARCH(".tif",C937)),"tif",IF(ISNUMBER(SEARCH(".las",C937)),"las",IF(ISNUMBER(SEARCH(".sdg",C937)),"sdg",IF(ISNUMBER(SEARCH(".xlsx",C937)),"xlsx",IF(ISNUMBER(SEARCH(".docx",C937)),"docx",IF(ISNUMBER(SEARCH(".rhistory",C937)),"rhistory",IF(ISNUMBER(SEARCH(".db",C937)),"db",IF(ISNUMBER(SEARCH(".jpg",C937)),"jpg",IF(ISNUMBER(SEARCH(".png",C937)),"png",IF(ISNUMBER(SEARCH(".mdb",C937)),"mdb",IF(ISNUMBER(SEARCH(".xml",C937)),"xml",IF(ISNUMBER(SEARCH(".xls",C937)),"xls",IF(ISNUMBER(SEARCH(".txt",C937)),"txt",IF(ISNUMBER(SEARCH(".tsf",C937)),"tsf",IF(ISNUMBER(SEARCH(".sch",C937)),"sch","ZIP oder R")))))))))))))))) -> las
A938: P:\I2535F001_KI-Explore\Bohrprotokolle_Schichtenverzeichnisse\K-UTEC_neu\TLUBN\anfrage_2025_02_k-utec\Aufschlussdokumente\108071\108071_E_Straussfurt_T2_1963 | B938: Straussfurt_T2_1963 | C938: 108071_E_Straussfurt_T2_1963_Edit_KORR_1-1000.tif | D938: =IF(ISNUMBER(SEARCH(".pdf",C938)),"pdf",IF(ISNUMBER(SEARCH(".tif",C938)),"tif",IF(ISNUMBER(SEARCH(".las",C938)),"las",IF(ISNUMBER(SEARCH(".sdg",C938)),"sdg",IF(ISNUMBER(SEARCH(".xlsx",C938)),"xlsx",IF(ISNUMBER(SEARCH(".docx",C938)),"docx",IF(ISNUMBER(SEARCH(".rhistory",C938)),"rhistory",IF(ISNUMBER(SEARCH(".db",C938)),"db",IF(ISNUMBER(SEARCH(".jpg",C938)),"jpg",IF(ISNUMBER(SEARCH(".png",C938)),"png",IF(ISNUMBER(SEARCH(".mdb",C938)),"mdb",IF(ISNUMBER(SEARCH(".xml",C938)),"xml",IF(ISNUMBER(SEARCH(".xls",C938)),"xls",IF(ISNUMBER(SEARCH(".txt",C938)),"txt",IF(ISNUMBER(SEARCH(".tsf",C938)),"tsf",IF(ISNUMBER(SEARCH(".sch",C938)),"sch","ZIP oder R")))))))))))))))) -> tif
A939: P:\I2535F001_KI-Explore\Bohrprotokolle_Schichtenverzeichnisse\K-UTEC_neu\TLUBN\anfrage_2025_02_k-utec\Aufschlussdokumente\108071\108071_E_Straussfurt_T2_1963 | B939: Straussfurt_T2_1963 | C939: 108071_E_Straussfurt_T2_1963_Edit_SPEZ_1-500.tif | D939: =IF(ISNUMBER(SEARCH(".pdf",C939)),"pdf",IF(ISNUMBER(SEARCH(".tif",C939)),"tif",IF(ISNUMBER(SEARCH(".las",C939)),"las",IF(ISNUMBER(SEARCH(".sdg",C939)),"sdg",IF(ISNUMBER(SEARCH(".xlsx",C939)),"xlsx",IF(ISNUMBER(SEARCH(".docx",C939)),"docx",IF(ISNUMBER(SEARCH(".rhistory",C939)),"rhistory",IF(ISNUMBER(SEARCH(".db",C939)),"db",IF(ISNUMBER(SEARCH(".jpg",C939)),"jpg",IF(ISNUMBER(SEARCH(".png",C939)),"png",IF(ISNUMBER(SEARCH(".mdb",C939)),"mdb",IF(ISNUMBER(SEARCH(".xml",C939)),"xml",IF(ISNUMBER(SEARCH(".xls",C939)),"xls",IF(ISNUMBER(SEARCH(".txt",C939)),"txt",IF(ISNUMBER(SEARCH(".tsf",C939)),"tsf",IF(ISNUMBER(SEARCH(".sch",C939)),"sch","ZIP oder R")))))))))))))))) -> tif
A940: P:\I2535F001_KI-Explore\Bohrprotokolle_Schichtenverzeichnisse\K-UTEC_neu\TLUBN\anfrage_2025_02_k-utec\Aufschlussdokumente\108071\108071_E_Straussfurt_T2_1963 | B940: Straussfurt_T2_1963 | C940: 108071_E_Straussfurt_T2_1963_REPORT_KORR.docx | D940: =IF(ISNUMBER(SEARCH(".pdf",C940)),"pdf",IF(ISNUMBER(SEARCH(".tif",C940)),"tif",IF(ISNUMBER(SEARCH(".las",C940)),"las",IF(ISNUMBER(SEARCH(".sdg",C940)),"sdg",IF(ISNUMBER(SEARCH(".xlsx",C940)),"xlsx",IF(ISNUMBER(SEARCH(".docx",C940)),"docx",IF(ISNUMBER(SEARCH(".rhistory",C940)),"rhistory",IF(ISNUMBER(SEARCH(".db",C940)),"db",IF(ISNUMBER(SEARCH(".jpg",C940)),"jpg",IF(ISNUMBER(SEARCH(".png",C940)),"png",IF(ISNUMBER(SEARCH(".mdb",C940)),"mdb",IF(ISNUMBER(SEARCH(".xml",C940)),"xml",IF(ISNUMBER(SEARCH(".xls",C940)),"xls",IF(ISNUMBER(SEARCH(".txt",C940)),"txt",IF(ISNUMBER(SEARCH(".tsf",C940)),"tsf",IF(ISNUMBER(SEARCH(".sch",C940)),"sch","ZIP oder R")))))))))))))))) -> docx
A941: P:\I2535F001_KI-Explore\Bohrprotokolle_Schichtenverzeichnisse\K-UTEC_neu\TLUBN\anfrage_2025_02_k-utec\Aufschlussdokumente\108071\108071_E_Straussfurt_T2_1963 | B941: Straussfurt_T2_1963 | C941: 108071_E_Straussfurt_T2_1963_REPORT_SPEZ.docx | D941: =IF(ISNUMBER(SEARCH(".pdf",C941)),"pdf",IF(ISNUMBER(SEARCH(".tif",C941)),"tif",IF(ISNUMBER(SEARCH(".las",C941)),"las",IF(ISNUMBER(SEARCH(".sdg",C941)),"sdg",IF(ISNUMBER(SEARCH(".xlsx",C941)),"xlsx",IF(ISNUMBER(SEARCH(".docx",C941)),"docx",IF(ISNUMBER(SEARCH(".rhistory",C941)),"rhistory",IF(ISNUMBER(SEARCH(".db",C941)),"db",IF(ISNUMBER(SEARCH(".jpg",C941)),"jpg",IF(ISNUMBER(SEARCH(".png",C941)),"png",IF(ISNUMBER(SEARCH(".mdb",C941)),"mdb",IF(ISNUMBER(SEARCH(".xml",C941)),"xml",IF(ISNUMBER(SEARCH(".xls",C941)),"xls",IF(ISNUMBER(SEARCH(".txt",C941)),"txt",IF(ISNUMBER(SEARCH(".tsf",C941)),"tsf",IF(ISNUMBER(SEARCH(".sch",C941)),"sch","ZIP oder R")))))))))))))))) -> docx
A942: P:\I2535F001_KI-Explore\Bohrprotokolle_Schichtenverzeichnisse\K-UTEC_neu\TLUBN\anfrage_2025_02_k-utec\Aufschlussdokumente\108071\108071_E_Straussfurt_T2_1963\Rohdaten | B942: Straussfurt_T2_1963 | C942: 108071_E_Straussfurt_T2_1963_Geophysik_01.las | D942: =IF(ISNUMBER(SEARCH(".pdf",C942)),"pdf",IF(ISNUMBER(SEARCH(".tif",C942)),"tif",IF(ISNUMBER(SEARCH(".las",C942)),"las",IF(ISNUMBER(SEARCH(".sdg",C942)),"sdg",IF(ISNUMBER(SEARCH(".xlsx",C942)),"xlsx",IF(ISNUMBER(SEARCH(".docx",C942)),"docx",IF(ISNUMBER(SEARCH(".rhistory",C942)),"rhistory",IF(ISNUMBER(SEARCH(".db",C942)),"db",IF(ISNUMBER(SEARCH(".jpg",C942)),"jpg",IF(ISNUMBER(SEARCH(".png",C942)),"png",IF(ISNUMBER(SEARCH(".mdb",C942)),"mdb",IF(ISNUMBER(SEARCH(".xml",C942)),"xml",IF(ISNUMBER(SEARCH(".xls",C942)),"xls",IF(ISNUMBER(SEARCH(".txt",C942)),"txt",IF(ISNUMBER(SEARCH(".tsf",C942)),"tsf",IF(ISNUMBER(SEARCH(".sch",C942)),"sch","ZIP oder R")))))))))))))))) -> las
A943: P:\I2535F001_KI-Explore\Bohrprotokolle_Schichtenverzeichnisse\K-UTEC_neu\TLUBN\anfrage_2025_02_k-utec\Aufschlussdokumente\108071\108071_E_Straussfurt_T2_1963\Rohdaten | B943: Straussfurt_T2_1963 | C943: 108071_E_Straussfurt_T2_1963_Geophysik_02.las | D943: =IF(ISNUMBER(SEARCH(".pdf",C943)),"pdf",IF(ISNUMBER(SEARCH(".tif",C943)),"tif",IF(ISNUMBER(SEARCH(".las",C943)),"las",IF(ISNUMBER(SEARCH(".sdg",C943)),"sdg",IF(ISNUMBER(SEARCH(".xlsx",C943)),"xlsx",IF(ISNUMBER(SEARCH(".docx",C943)),"docx",IF(ISNUMBER(SEARCH(".rhistory",C943)),"rhistory",IF(ISNUMBER(SEARCH(".db",C943)),"db",IF(ISNUMBER(SEARCH(".jpg",C943)),"jpg",IF(ISNUMBER(SEARCH(".png",C943)),"png",IF(ISNUMBER(SEARCH(".mdb",C943)),"mdb",IF(ISNUMBER(SEARCH(".xml",C943)),"xml",IF(ISNUMBER(SEARCH(".xls",C943)),"xls",IF(ISNUMBER(SEARCH(".txt",C943)),"txt",IF(ISNUMBER(SEARCH(".tsf",C943)),"tsf",IF(ISNUMBER(SEARCH(".sch",C943)),"sch","ZIP oder R")))))))))))))))) -> las
... A1139: P:\I2535F001_KI-Explore\Bohrprotokolle_Schichtenverzeichnisse\K-UTEC_neu\TLUBN\anfrage_2025_02_k-utec\Aufschlussdokumente\620675 | B1139: Ballstedt_1_1963 | C1139: 620675_Kal_Ballstedt_1_1973_Bohrjournal_02_Anlagen.pdf | D1139: =IF(ISNUMBER(SEARCH(".pdf",C1139)),"pdf",IF(ISNUMBER(SEARCH(".tif",C1139)),"tif",IF(ISNUMBER(SEARCH(".las",C1139)),"las",IF(ISNUMBER(SEARCH(".sdg",C1139)),"sdg",IF(ISNUMBER(SEARCH(".xlsx",C1139)),"xlsx",IF(ISNUMBER(SEARCH(".docx",C1139)),"docx",IF(ISNUMBER(SEARCH(".rhistory",C1139)),"rhistory",IF(ISNUMBER(SEARCH(".db",C1139)),"db",IF(ISNUMBER(SEARCH(".jpg",C1139)),"jpg",IF(ISNUMBER(SEARCH(".png",C1139)),"png",IF(ISNUMBER(SEARCH(".mdb",C1139)),"mdb",IF(ISNUMBER(SEARCH(".xml",C1139)),"xml",IF(ISNUMBER(SEARCH(".xls",C1139)),"xls",IF(ISNUMBER(SEARCH(".txt",C1139)),"txt",IF(ISNUMBER(SEARCH(".tsf",C1139)),"tsf",IF(ISNUMBER(SEARCH(".sch",C1139)),"sch","ZIP oder R")))))))))))))))) -> pdf
A1140: P:\I2535F001_KI-Explore\Bohrprotokolle_Schichtenverzeichnisse\K-UTEC_neu\TLUBN\anfrage_2025_02_k-utec\Aufschlussdokumente\621286 | C1140: 50_Ro_4929.pdf | D1140: =IF(ISNUMBER(SEARCH(".pdf",C1140)),"pdf",IF(ISNUMBER(SEARCH(".tif",C1140)),"tif",IF(ISNUMBER(SEARCH(".las",C1140)),"las",IF(ISNUMBER(SEARCH(".sdg",C1140)),"sdg",IF(ISNUMBER(SEARCH(".xlsx",C1140)),"xlsx",IF(ISNUMBER(SEARCH(".docx",C1140)),"docx",IF(ISNUMBER(SEARCH(".rhistory",C1140)),"rhistory",IF(ISNUMBER(SEARCH(".db",C1140)),"db",IF(ISNUMBER(SEARCH(".jpg",C1140)),"jpg",IF(ISNUMBER(SEARCH(".png",C1140)),"png",IF(ISNUMBER(SEARCH(".mdb",C1140)),"mdb",IF(ISNUMBER(SEARCH(".xml",C1140)),"xml",IF(ISNUMBER(SEARCH(".xls",C1140)),"xls",IF(ISNUMBER(SEARCH(".txt",C1140)),"txt",IF(ISNUMBER(SEARCH(".tsf",C1140)),"tsf",IF(ISNUMBER(SEARCH(".sch",C1140)),"sch","ZIP oder R")))))))))))))))) -> pdf
A1141: P:\I2535F001_KI-Explore\Bohrprotokolle_Schichtenverzeichnisse\K-UTEC_neu\TLUBN\anfrage_2025_02_k-utec\Aufschlussdokumente\621286 | B1141: Behringen_1_1962 | C1141: 621286_E_Behringen_01_1962_01.LAS | D1141: =IF(ISNUMBER(SEARCH(".pdf",C1141)),"pdf",IF(ISNUMBER(SEARCH(".tif",C1141)),"tif",IF(ISNUMBER(SEARCH(".las",C1141)),"las",IF(ISNUMBER(SEARCH(".sdg",C1141)),"sdg",IF(ISNUMBER(SEARCH(".xlsx",C1141)),"xlsx",IF(ISNUMBER(SEARCH(".docx",C1141)),"docx",IF(ISNUMBER(SEARCH(".rhistory",C1141)),"rhistory",IF(ISNUMBER(SEARCH(".db",C1141)),"db",IF(ISNUMBER(SEARCH(".jpg",C1141)),"jpg",IF(ISNUMBER(SEARCH(".png",C1141)),"png",IF(ISNUMBER(SEARCH(".mdb",C1141)),"mdb",IF(ISNUMBER(SEARCH(".xml",C1141)),"xml",IF(ISNUMBER(SEARCH(".xls",C1141)),"xls",IF(ISNUMBER(SEARCH(".txt",C1141)),"txt",IF(ISNUMBER(SEARCH(".tsf",C1141)),"tsf",IF(ISNUMBER(SEARCH(".sch",C1141)),"sch","ZIP oder R")))))))))))))))) -> las
A1142: P:\I2535F001_KI-Explore\Bohrprotokolle_Schichtenverzeichnisse\K-UTEC_neu\TLUBN\anfrage_2025_02_k-utec\Aufschlussdokumente\621286 | B1142: Behringen_1_1962 | C1142: 621286_E_Behringen_01_1962_Geophysik_LAS.zip | D1142: =IF(ISNUMBER(SEARCH(".pdf",C1142)),"pdf",IF(ISNUMBER(SEARCH(".tif",C1142)),"tif",IF(ISNUMBER(SEARCH(".las",C1142)),"las",IF(ISNUMBER(SEARCH(".sdg",C1142)),"sdg",IF(ISNUMBER(SEARCH(".xlsx",C1142)),"xlsx",IF(ISNUMBER(SEARCH(".docx",C1142)),"docx",IF(ISNUMBER(SEARCH(".rhistory",C1142)),"rhistory",IF(ISNUMBER(SEARCH(".db",C1142)),"db",IF(ISNUMBER(SEARCH(".jpg",C1142)),"jpg",IF(ISNUMBER(SEARCH(".png",C1142)),"png",IF(ISNUMBER(SEARCH(".mdb",C1142)),"mdb",IF(ISNUMBER(SEARCH(".xml",C1142)),"xml",IF(ISNUMBER(SEARCH(".xls",C1142)),"xls",IF(ISNUMBER(SEARCH(".txt",C1142)),"txt",IF(ISNUMBER(SEARCH(".tsf",C1142)),"tsf",IF(ISNUMBER(SEARCH(".sch",C1142)),"sch","ZIP oder R")))))))))))))))) -> ZIP oder R
A1143: P:\I2535F001_KI-Explore\Bohrprotokolle_Schichtenverzeichnisse\K-UTEC_neu\TLUBN\anfrage_2025_02_k-utec\Aufschlussdokumente\621286 | B1143: Behringen_1_1962 | C1143: Behn01_GR_NG_OK-UK_Cali.las | D1143: =IF(ISNUMBER(SEARCH(".pdf",C1143)),"pdf",IF(ISNUMBER(SEARCH(".tif",C1143)),"tif",IF(ISNUMBER(SEARCH(".las",C1143)),"las",IF(ISNUMBER(SEARCH(".sdg",C1143)),"sdg",IF(ISNUMBER(SEARCH(".xlsx",C1143)),"xlsx",IF(ISNUMBER(SEARCH(".docx",C1143)),"docx",IF(ISNUMBER(SEARCH(".rhistory",C1143)),"rhistory",IF(ISNUMBER(SEARCH(".db",C1143)),"db",IF(ISNUMBER(SEARCH(".jpg",C1143)),"jpg",IF(ISNUMBER(SEARCH(".png",C1143)),"png",IF(ISNUMBER(SEARCH(".mdb",C1143)),"mdb",IF(ISNUMBER(SEARCH(".xml",C1143)),"xml",IF(ISNUMBER(SEARCH(".xls",C1143)),"xls",IF(ISNUMBER(SEARCH(".txt",C1143)),"txt",IF(ISNUMBER(SEARCH(".tsf",C1143)),"tsf",IF(ISNUMBER(SEARCH(".sch",C1143)),"sch","ZIP oder R")))))))))))))))) -> las
A1144: P:\I2535F001_KI-Explore\Bohrprotokolle_Schichtenverzeichnisse\K-UTEC_neu\TLUBN\anfrage_2025_02_k-utec\Aufschlussdokumente\621286 | B1144: Behringen_1_1962 | C1144: BEHN1.LAS | D1144: =IF(ISNUMBER(SEARCH(".pdf",C1144)),"pdf",IF(ISNUMBER(SEARCH(".tif",C1144)),"tif",IF(ISNUMBER(SEARCH(".las",C1144)),"las",IF(ISNUMBER(SEARCH(".sdg",C1144)),"sdg",IF(ISNUMBER(SEARCH(".xlsx",C1144)),"xlsx",IF(ISNUMBER(SEARCH(".docx",C1144)),"docx",IF(ISNUMBER(SEARCH(".rhistory",C1144)),"rhistory",IF(ISNUMBER(SEARCH(".db",C1144)),"db",IF(ISNUMBER(SEARCH(".jpg",C1144)),"jpg",IF(ISNUMBER(SEARCH(".png",C1144)),"png",IF(ISNUMBER(SEARCH(".mdb",C1144)),"mdb",IF(ISNUMBER(SEARCH(".xml",C1144)),"xml",IF(ISNUMBER(SEARCH(".xls",C1144)),"xls",IF(ISNUMBER(SEARCH(".txt",C1144)),"txt",IF(ISNUMBER(SEARCH(".tsf",C1144)),"tsf",IF(ISNUMBER(SEARCH(".sch",C1144)),"sch","ZIP oder R")))))))))))))))) -> las
A1145: P:\I2535F001_KI-Explore\Bohrprotokolle_Schichtenverzeichnisse\K-UTEC_neu\TLUBN\anfrage_2025_02_k-utec\Aufschlussdokumente\621286 | B1145: Behringen_1_1962 | C1145: BEHN1A.LAS | D1145: =IF(ISNUMBER(SEARCH(".pdf",C1145)),"pdf",IF(ISNUMBER(SEARCH(".tif",C1145)),"tif",IF(ISNUMBER(SEARCH(".las",C1145)),"las",IF(ISNUMBER(SEARCH(".sdg",C1145)),"sdg",IF(ISNUMBER(SEARCH(".xlsx",C1145)),"xlsx",IF(ISNUMBER(SEARCH(".docx",C1145)),"docx",IF(ISNUMBER(SEARCH(".rhistory",C1145)),"rhistory",IF(ISNUMBER(SEARCH(".db",C1145)),"db",IF(ISNUMBER(SEARCH(".jpg",C1145)),"jpg",IF(ISNUMBER(SEARCH(".png",C1145)),"png",IF(ISNUMBER(SEARCH(".mdb",C1145)),"mdb",IF(ISNUMBER(SEARCH(".xml",C1145)),"xml",IF(ISNUMBER(SEARCH(".xls",C1145)),"xls",IF(ISNUMBER(SEARCH(".txt",C1145)),"txt",IF(ISNUMBER(SEARCH(".tsf",C1145)),"tsf",IF(ISNUMBER(SEARCH(".sch",C1145)),"sch","ZIP oder R")))))))))))))))) -> las
A1146: P:\I2535F001_KI-Explore\Bohrprotokolle_Schichtenverzeichnisse\K-UTEC_neu\TLUBN\anfrage_2025_02_k-utec\Aufschlussdokumente\621286 | B1146: Behringen_1_1962 | C1146: BEHN1AA.LAS | D1146: =IF(ISNUMBER(SEARCH(".pdf",C1146)),"pdf",IF(ISNUMBER(SEARCH(".tif",C1146)),"tif",IF(ISNUMBER(SEARCH(".las",C1146)),"las",IF(ISNUMBER(SEARCH(".sdg",C1146)),"sdg",IF(ISNUMBER(SEARCH(".xlsx",C1146)),"xlsx",IF(ISNUMBER(SEARCH(".docx",C1146)),"docx",IF(ISNUMBER(SEARCH(".rhistory",C1146)),"rhistory",IF(ISNUMBER(SEARCH(".db",C1146)),"db",IF(ISNUMBER(SEARCH(".jpg",C1146)),"jpg",IF(ISNUMBER(SEARCH(".png",C1146)),"png",IF(ISNUMBER(SEARCH(".mdb",C1146)),"mdb",IF(ISNUMBER(SEARCH(".xml",C1146)),"xml",IF(ISNUMBER(SEARCH(".xls",C1146)),"xls",IF(ISNUMBER(SEARCH(".txt",C1146)),"txt",IF(ISNUMBER(SEARCH(".tsf",C1146)),"tsf",IF(ISNUMBER(SEARCH(".sch",C1146)),"sch","ZIP oder R")))))))))))))))) -> las
A1147: P:\I2535F001_KI-Explore\Bohrprotokolle_Schichtenverzeichnisse\K-UTEC_neu\TLUBN\anfrage_2025_02_k-utec\Aufschlussdokumente\621286 | B1147: Behringen_1_1962 | C1147: BEHN1AAA.LAS | D1147: =IF(ISNUMBER(SEARCH(".pdf",C1147)),"pdf",IF(ISNUMBER(SEARCH(".tif",C1147)),"tif",IF(ISNUMBER(SEARCH(".las",C1147)),"las",IF(ISNUMBER(SEARCH(".sdg",C1147)),"sdg",IF(ISNUMBER(SEARCH(".xlsx",C1147)),"xlsx",IF(ISNUMBER(SEARCH(".docx",C1147)),"docx",IF(ISNUMBER(SEARCH(".rhistory",C1147)),"rhistory",IF(ISNUMBER(SEARCH(".db",C1147)),"db",IF(ISNUMBER(SEARCH(".jpg",C1147)),"jpg",IF(ISNUMBER(SEARCH(".png",C1147)),"png",IF(ISNUMBER(SEARCH(".mdb",C1147)),"mdb",IF(ISNUMBER(SEARCH(".xml",C1147)),"xml",IF(ISNUMBER(SEARCH(".xls",C1147)),"xls",IF(ISNUMBER(SEARCH(".txt",C1147)),"txt",IF(ISNUMBER(SEARCH(".tsf",C1147)),"tsf",IF(ISNUMBER(SEARCH(".sch",C1147)),"sch","ZIP oder R")))))))))))))))) -> las
A1148: P:\I2535F001_KI-Explore\Bohrprotokolle_Schichtenverzeichnisse\K-UTEC_neu\TLUBN\anfrage_2025_02_k-utec\Aufschlussdokumente\621286 | B1148: Behringen_1_1962 | C1148: BEHN1AB.LAS | D1148: =IF(ISNUMBER(SEARCH(".pdf",C1148)),"pdf",IF(ISNUMBER(SEARCH(".tif",C1148)),"tif",IF(ISNUMBER(SEARCH(".las",C1148)),"las",IF(ISNUMBER(SEARCH(".sdg",C1148)),"sdg",IF(ISNUMBER(SEARCH(".xlsx",C1148)),"xlsx",IF(ISNUMBER(SEARCH(".docx",C1148)),"docx",IF(ISNUMBER(SEARCH(".rhistory",C1148)),"rhistory",IF(ISNUMBER(SEARCH(".db",C1148)),"db",IF(ISNUMBER(SEARCH(".jpg",C1148)),"jpg",IF(ISNUMBER(SEARCH(".png",C1148)),"png",IF(ISNUMBER(SEARCH(".mdb",C1148)),"mdb",IF(ISNUMBER(SEARCH(".xml",C1148)),"xml",IF(ISNUMBER(SEARCH(".xls",C1148)),"xls",IF(ISNUMBER(SEARCH(".txt",C1148)),"txt",IF(ISNUMBER(SEARCH(".tsf",C1148)),"tsf",IF(ISNUMBER(SEARCH(".sch",C1148)),"sch","ZIP oder R")))))))))))))))) -> las
A1149: P:\I2535F001_KI-Explore\Bohrprotokolle_Schichtenverzeichnisse\K-UTEC_neu\TLUBN\anfrage_2025_02_k-utec\Aufschlussdokumente\621286 | B1149: Behringen_1_1962 | C1149: BEHN1B.LAS | D1149: =IF(ISNUMBER(SEARCH(".pdf",C1149)),"pdf",IF(ISNUMBER(SEARCH(".tif",C1149)),"tif",IF(ISNUMBER(SEARCH(".las",C1149)),"las",IF(ISNUMBER(SEARCH(".sdg",C1149)),"sdg",IF(ISNUMBER(SEARCH(".xlsx",C1149)),"xlsx",IF(ISNUMBER(SEARCH(".docx",C1149)),"docx",IF(ISNUMBER(SEARCH(".rhistory",C1149)),"rhistory",IF(ISNUMBER(SEARCH(".db",C1149)),"db",IF(ISNUMBER(SEARCH(".jpg",C1149)),"jpg",IF(ISNUMBER(SEARCH(".png",C1149)),"png",IF(ISNUMBER(SEARCH(".mdb",C1149)),"mdb",IF(ISNUMBER(SEARCH(".xml",C1149)),"xml",IF(ISNUMBER(SEARCH(".xls",C1149)),"xls",IF(ISNUMBER(SEARCH(".txt",C1149)),"txt",IF(ISNUMBER(SEARCH(".tsf",C1149)),"tsf",IF(ISNUMBER(SEARCH(".sch",C1149)),"sch","ZIP oder R")))))))))))))))) -> las
A1150: P:\I2535F001_KI-Explore\Bohrprotokolle_Schichtenverzeichnisse\K-UTEC_neu\TLUBN\anfrage_2025_02_k-utec\Aufschlussdokumente\621286 | B1150: Behringen_1_1962 | C1150: BEHN1BA.LAS | D1150: =IF(ISNUMBER(SEARCH(".pdf",C1150)),"pdf",IF(ISNUMBER(SEARCH(".tif",C1150)),"tif",IF(ISNUMBER(SEARCH(".las",C1150)),"las",IF(ISNUMBER(SEARCH(".sdg",C1150)),"sdg",IF(ISNUMBER(SEARCH(".xlsx",C1150)),"xlsx",IF(ISNUMBER(SEARCH(".docx",C1150)),"docx",IF(ISNUMBER(SEARCH(".rhistory",C1150)),"rhistory",IF(ISNUMBER(SEARCH(".db",C1150)),"db",IF(ISNUMBER(SEARCH(".jpg",C1150)),"jpg",IF(ISNUMBER(SEARCH(".png",C1150)),"png",IF(ISNUMBER(SEARCH(".mdb",C1150)),"mdb",IF(ISNUMBER(SEARCH(".xml",C1150)),"xml",IF(ISNUMBER(SEARCH(".xls",C1150)),"xls",IF(ISNUMBER(SEARCH(".txt",C1150)),"txt",IF(ISNUMBER(SEARCH(".tsf",C1150)),"tsf",IF(ISNUMBER(SEARCH(".sch",C1150)),"sch","ZIP oder R")))))))))))))))) -> las
...

Sheet Bohrungen
A1: ID | B1: Bohrungen | C1: pdf | D1: tif | E1: sdg | F1: xlsx | G1: docx | H1: las | I1: db | J1: rhistory | K1: mdb | L1: xml | M1: jpg | N1: png | O1: xls | P1: txt | Q1: ZIP oder R | R1: tsf | S1: sch | U1: Kategorie | V1: Kategorie_ID
A2: 1 | B2: Allmenhausen_10_1960 | C2: =IF(SUMPRODUCT(('alle Dateien'!B:B=Bohrungen!B2)*('alle Dateien'!D:D="pdf"))>0,1,0) -> 1 | D2: =IF(SUMPRODUCT(('alle Dateien'!B:B=Bohrungen!B2)*('alle Dateien'!D:D="tif"))>0,1,0) -> 1 | E2: =IF(SUMPRODUCT(('alle Dateien'!B:B=Bohrungen!B2)*('alle Dateien'!D:D="sdg"))>0,1,0) -> 0 | F2: =IF(SUMPRODUCT(('alle Dateien'!B:B=Bohrungen!B2)*('alle Dateien'!D:D="xlsx"))>0,1,0) -> 0 | G2: =IF(SUMPRODUCT(('alle Dateien'!B:B=Bohrungen!B2)*('alle Dateien'!D:D="docx"))>0,1,0) -> 0 | H2: =IF(SUMPRODUCT(('alle Dateien'!B:B=Bohrungen!B2)*('alle Dateien'!D:D="las"))>0,1,0) -> 0 | I2: =IF(SUMPRODUCT(('alle Dateien'!B:B=Bohrungen!B2)*('alle Dateien'!D:D="db"))>0,1,0) -> 0 | J2: =IF(SUMPRODUCT(('alle Dateien'!B:B=Bohrungen!B2)*('alle Dateien'!D:D="rhistory"))>0,1,0) -> 0 | K2: =IF(SUMPRODUCT(('alle Dateien'!B:B=Bohrungen!B2)*('alle Dateien'!D:D="mdb"))>0,1,0) -> 0 | L2: =IF(SUMPRODUCT(('alle Dateien'!B:B=Bohrungen!B2)*('alle Dateien'!D:D="xml"))>0,1,0) -> 0 | M2: =IF(SUMPRODUCT(('alle Dateien'!B:B=Bohrungen!B2)*('alle Dateien'!D:D="jpg"))>0,1,0) -> 0 | N2: =IF(SUMPRODUCT(('alle Dateien'!B:B=Bohrungen!B2)*('alle Dateien'!D:D="png"))>0,1,0) -> 0 | O2: =IF(SUMPRODUCT(('alle Dateien'!B:B=Bohrungen!B2)*('alle Dateien'!D:D="xls"))>0,1,0) -> 0 | P2: =IF(SUMPRODUCT(('alle Dateien'!B:B=Bohrungen!B2)*('alle Dateien'!D:D="txt"))>0,1,0) -> 0 | Q2: =IF(SUMPRODUCT(('alle Dateien'!B:B=Bohrungen!B2)*('alle Dateien'!D:D="ZIP oder R"))>0,1,0) -> 0 | R2: =IF(SUMPRODUCT(('alle Dateien'!B:B=Bohrungen!B2)*('alle Dateien'!D:D="tsf"))>0,1,0) -> 0 | S2: =IF(SUMPRODUCT(('alle Dateien'!B:B=Bohrungen!B2)*('alle Dateien'!D:D="sch"))>0,1,0) -> 0 | U2: =CONCATENATE(C2,D2,E2,F2,G2,H2,I2,J2,K2,L2,M2,N2,O2,P2,Q2,R2,S2,) -> 11000000000000000 | V2: =VLOOKUP(U2,Kategorie!B:C,2,FALSE) -> pdf/ tif
A3: 2 | B3: Allmenhausen_11_1960 | C3: =IF(SUMPRODUCT(('alle Dateien'!B:B=Bohrungen!B3)*('alle Dateien'!D:D="pdf"))>0,1,0) -> 1 | D3: =IF(SUMPRODUCT(('alle Dateien'!B:B=Bohrungen!B3)*('alle Dateien'!D:D="tif"))>0,1,0) -> 0 | E3: =IF(SUMPRODUCT(('alle Dateien'!B:B=Bohrungen!B3)*('alle Dateien'!D:D="sdg"))>0,1,0) -> 0 | F3: =IF(SUMPRODUCT(('alle Dateien'!B:B=Bohrungen!B3)*('alle Dateien'!D:D="xlsx"))>0,1,0) -> 0 | G3: =IF(SUMPRODUCT(('alle Dateien'!B:B=Bohrungen!B3)*('alle Dateien'!D:D="docx"))>0,1,0) -> 0 | H3: =IF(SUMPRODUCT(('alle Dateien'!B:B=Bohrungen!B3)*('alle Dateien'!D:D="las"))>0,1,0) -> 0 | I3: =IF(SUMPRODUCT(('alle Dateien'!B:B=Bohrungen!B3)*('alle Dateien'!D:D="db"))>0,1,0) -> 0 | J3: =IF(SUMPRODUCT(('alle Dateien'!B:B=Bohrungen!B3)*('alle Dateien'!D:D="rhistory"))>0,1,0) -> 0 | K3: =IF(SUMPRODUCT(('alle Dateien'!B:B=Bohrungen!B3)*('alle Dateien'!D:D="mdb"))>0,1,0) -> 0 | L3: =IF(SUMPRODUCT(('alle Dateien'!B:B=Bohrungen!B3)*('alle Dateien'!D:D="xml"))>0,1,0) -> 0 | M3: =IF(SUMPRODUCT(('alle Dateien'!B:B=Bohrungen!B3)*('alle Dateien'!D:D="jpg"))>0,1,0) -> 0 | N3: =IF(SUMPRODUCT(('alle Dateien'!B:B=Bohrungen!B3)*('alle Dateien'!D:D="png"))>0,1,0) -> 0 | O3: =IF(SUMPRODUCT(('alle Dateien'!B:B=Bohrungen!B3)*('alle Dateien'!D:D="xls"))>0,1,0) -> 0 | P3: =IF(SUMPRODUCT(('alle Dateien'!B:B=Bohrungen!B3)*('alle Dateien'!D:D="txt"))>0,1,0) -> 0 | Q3: =IF(SUMPRODUCT(('alle Dateien'!B:B=Bohrungen!B3)*('alle Dateien'!D:D="ZIP oder R"))>0,1,0) -> 0 | R3: =IF(SUMPRODUCT(('alle Dateien'!B:B=Bohrungen!B3)*('alle Dateien'!D:D="tsf"))>0,1,0) -> 0 | S3: =IF(SUMPRODUCT(('alle Dateien'!B:B=Bohrungen!B3)*('alle Dateien'!D:D="sch"))>0,1,0) -> 0 | U3: =CONCATENATE(C3,D3,E3,F3,G3,H3,I3,J3,K3,L3,M3,N3,O3,P3,Q3,R3,S3,) -> 10000000000000000 | V3: =VLOOKUP(U3,Kategorie!B:C,2,FALSE) -> pdf
A4: 3 | B4: Allmenhausen_2_1959 | C4: =IF(SUMPRODUCT(('alle Dateien'!B:B=Bohrungen!B4)*('alle Dateien'!D:D="pdf"))>0,1,0) -> 1 | D4: =IF(SUMPRODUCT(('alle Dateien'!B:B=Bohrungen!B4)*('alle Dateien'!D:D="tif"))>0,1,0) -> 0 | E4: =IF(SUMPRODUCT(('alle Dateien'!B:B=Bohrungen!B4)*('alle Dateien'!D:D="sdg"))>0,1,0) -> 0 | F4: =IF(SUMPRODUCT(('alle Dateien'!B:B=Bohrungen!B4)*('alle Dateien'!D:D="xlsx"))>0,1,0) -> 0 | G4: =IF(SUMPRODUCT(('alle Dateien'!B:B=Bohrungen!B4)*('alle Dateien'!D:D="docx"))>0,1,0) -> 0 | H4: =IF(SUMPRODUCT(('alle Dateien'!B:B=Bohrungen!B4)*('alle Dateien'!D:D="las"))>0,1,0) -> 0 | I4: =IF(SUMPRODUCT(('alle Dateien'!B:B=Bohrungen!B4)*('alle Dateien'!D:D="db"))>0,1,0) -> 0 | J4: =IF(SUMPRODUCT(('alle Dateien'!B:B=Bohrungen!B4)*('alle Dateien'!D:D="rhistory"))>0,1,0) -> 0 | K4: =IF(SUMPRODUCT(('alle Dateien'!B:B=Bohrungen!B4)*('alle Dateien'!D:D="mdb"))>0,1,0) -> 0 | L4: =IF(SUMPRODUCT(('alle Dateien'!B:B=Bohrungen!B4)*('alle Dateien'!D:D="xml"))>0,1,0) -> 0 | M4: =IF(SUMPRODUCT(('alle Dateien'!B:B=Bohrungen!B4)*('alle Dateien'!D:D="jpg"))>0,1,0) -> 0 | N4: =IF(SUMPRODUCT(('alle Dateien'!B:B=Bohrungen!B4)*('alle Dateien'!D:D="png"))>0,1,0) -> 0 | O4: =IF(SUMPRODUCT(('alle Dateien'!B:B=Bohrungen!B4)*('alle Dateien'!D:D="xls"))>0,1,0) -> 0 | P4: =IF(SUMPRODUCT(('alle Dateien'!B:B=Bohrungen!B4)*('alle Dateien'!D:D="txt"))>0,1,0) -> 0 | Q4: =IF(SUMPRODUCT(('alle Dateien'!B:B=Bohrungen!B4)*('alle Dateien'!D:D="ZIP oder R"))>0,1,0) -> 0 | R4: =IF(SUMPRODUCT(('alle Dateien'!B:B=Bohrungen!B4)*('alle Dateien'!D:D="tsf"))>0,1,0) -> 0 | S4: =IF(SUMPRODUCT(('alle Dateien'!B:B=Bohrungen!B4)*('alle Dateien'!D:D="sch"))>0,1,0) -> 0 | U4: =CONCATENATE(C4,D4,E4,F4,G4,H4,I4,J4,K4,L4,M4,N4,O4,P4,Q4,R4,S4,) -> 10000000000000000 | V4: =VLOOKUP(U4,Kategorie!B:C,2,FALSE) -> pdf
A5: 4 | B5: Allmenhausen_32_1968 | C5: =IF(SUMPRODUCT(('alle Dateien'!B:B=Bohrungen!B5)*('alle Dateien'!D:D="pdf"))>0,1,0) -> 1 | D5: =IF(SUMPRODUCT(('alle Dateien'!B:B=Bohrungen!B5)*('alle Dateien'!D:D="tif"))>0,1,0) -> 0 | E5: =IF(SUMPRODUCT(('alle Dateien'!B:B=Bohrungen!B5)*('alle Dateien'!D:D="sdg"))>0,1,0) -> 0 | F5: =IF(SUMPRODUCT(('alle Dateien'!B:B=Bohrungen!B5)*('alle Dateien'!D:D="xlsx"))>0,1,0) -> 0 | G5: =IF(SUMPRODUCT(('alle Dateien'!B:B=Bohrungen!B5)*('alle Dateien'!D:D="docx"))>0,1,0) -> 0 | H5: =IF(SUMPRODUCT(('alle Dateien'!B:B=Bohrungen!B5)*('alle Dateien'!D:D="las"))>0,1,0) -> 0 | I5: =IF(SUMPRODUCT(('alle Dateien'!B:B=Bohrungen!B5)*('alle Dateien'!D:D="db"))>0,1,0) -> 0 | J5: =IF(SUMPRODUCT(('alle Dateien'!B:B=Bohrungen!B5)*('alle Dateien'!D:D="rhistory"))>0,1,0) -> 0 | K5: =IF(SUMPRODUCT(('alle Dateien'!B:B=Bohrungen!B5)*('alle Dateien'!D:D="mdb"))>0,1,0) -> 0 | L5: =IF(SUMPRODUCT(('alle Dateien'!B:B=Bohrungen!B5)*('alle Dateien'!D:D="xml"))>0,1,0) -> 0 | M5: =IF(SUMPRODUCT(('alle Dateien'!B:B=Bohrungen!B5)*('alle Dateien'!D:D="jpg"))>0,1,0) -> 0 | N5: =IF(SUMPRODUCT(('alle Dateien'!B:B=Bohrungen!B5)*('alle Dateien'!D:D="png"))>0,1,0) -> 0 | O5: =IF(SUMPRODUCT(('alle Dateien'!B:B=Bohrungen!B5)*('alle Dateien'!D:D="xls"))>0,1,0) -> 0 | P5: =IF(SUMPRODUCT(('alle Dateien'!B:B=Bohrungen!B5)*('alle Dateien'!D:D="txt"))>0,1,0) -> 0 | Q5: =IF(SUMPRODUCT(('alle Dateien'!B:B=Bohrungen!B5)*('alle Dateien'!D:D="ZIP oder R"))>0,1,0) -> 0 | R5: =IF(SUMPRODUCT(('alle Dateien'!B:B=Bohrungen!B5)*('alle Dateien'!D:D="tsf"))>0,1,0) -> 0 | S5: =IF(SUMPRODUCT(('alle Dateien'!B:B=Bohrungen!B5)*('alle Dateien'!D:D="sch"))>0,1,0) -> 0 | U5: =CONCATENATE(C5,D5,E5,F5,G5,H5,I5,J5,K5,L5,M5,N5,O5,P5,Q5,R5,S5,) -> 10000000000000000 | V5: =VLOOKUP(U5,Kategorie!B:C,2,FALSE) -> pdf
A6: 5 | B6: Allmenhausen_33_1968 | C6: =IF(SUMPRODUCT(('alle Dateien'!B:B=Bohrungen!B6)*('alle Dateien'!D:D="pdf"))>0,1,0) -> 1 | D6: =IF(SUMPRODUCT(('alle Dateien'!B:B=Bohrungen!B6)*('alle Dateien'!D:D="tif"))>0,1,0) -> 0 | E6: =IF(SUMPRODUCT(('alle Dateien'!B:B=Bohrungen!B6)*('alle Dateien'!D:D="sdg"))>0,1,0) -> 0 | F6: =IF(SUMPRODUCT(('alle Dateien'!B:B=Bohrungen!B6)*('alle Dateien'!D:D="xlsx"))>0,1,0) -> 0 | G6: =IF(SUMPRODUCT(('alle Dateien'!B:B=Bohrungen!B6)*('alle Dateien'!D:D="docx"))>0,1,0) -> 0 | H6: =IF(SUMPRODUCT(('alle Dateien'!B:B=Bohrungen!B6)*('alle Dateien'!D:D="las"))>0,1,0) -> 0 | I6: =IF(SUMPRODUCT(('alle Dateien'!B:B=Bohrungen!B6)*('alle Dateien'!D:D="db"))>0,1,0) -> 0 | J6: =IF(SUMPRODUCT(('alle Dateien'!B:B=Bohrungen!B6)*('alle Dateien'!D:D="rhistory"))>0,1,0) -> 0 | K6: =IF(SUMPRODUCT(('alle Dateien'!B:B=Bohrungen!B6)*('alle Dateien'!D:D="mdb"))>0,1,0) -> 0 | L6: =IF(SUMPRODUCT(('alle Dateien'!B:B=Bohrungen!B6)*('alle Dateien'!D:D="xml"))>0,1,0) -> 0 | M6: =IF(SUMPRODUCT(('alle Dateien'!B:B=Bohrungen!B6)*('alle Dateien'!D:D="jpg"))>0,1,0) -> 0 | N6: =IF(SUMPRODUCT(('alle Dateien'!B:B=Bohrungen!B6)*('alle Dateien'!D:D="png"))>0,1,0) -> 0 | O6: =IF(SUMPRODUCT(('alle Dateien'!B:B=Bohrungen!B6)*('alle Dateien'!D:D="xls"))>0,1,0) -> 0 | P6: =IF(SUMPRODUCT(('alle Dateien'!B:B=Bohrungen!B6)*('alle Dateien'!D:D="txt"))>0,1,0) -> 0 | Q6: =IF(SUMPRODUCT(('alle Dateien'!B:B=Bohrungen!B6)*('alle Dateien'!D:D="ZIP oder R"))>0,1,0) -> 0 | R6: =IF(SUMPRODUCT(('alle Dateien'!B:B=Bohrungen!B6)*('alle Dateien'!D:D="tsf"))>0,1,0) -> 0 | S6: =IF(SUMPRODUCT(('alle Dateien'!B:B=Bohrungen!B6)*('alle Dateien'!D:D="sch"))>0,1,0) -> 0 | U6: =CONCATENATE(C6,D6,E6,F6,G6,H6,I6,J6,K6,L6,M6,N6,O6,P6,Q6,R6,S6,) -> 10000000000000000 | V6: =VLOOKUP(U6,Kategorie!B:C,2,FALSE) -> pdf
A7: 6 | B7: Allmenhausen_34_1969 | C7: =IF(SUMPRODUCT(('alle Dateien'!B:B=Bohrungen!B7)*('alle Dateien'!D:D="pdf"))>0,1,0) -> 1 | D7: =IF(SUMPRODUCT(('alle Dateien'!B:B=Bohrungen!B7)*('alle Dateien'!D:D="tif"))>0,1,0) -> 0 | E7: =IF(SUMPRODUCT(('alle Dateien'!B:B=Bohrungen!B7)*('alle Dateien'!D:D="sdg"))>0,1,0) -> 0 | F7: =IF(SUMPRODUCT(('alle Dateien'!B:B=Bohrungen!B7)*('alle Dateien'!D:D="xlsx"))>0,1,0) -> 0 | G7: =IF(SUMPRODUCT(('alle Dateien'!B:B=Bohrungen!B7)*('alle Dateien'!D:D="docx"))>0,1,0) -> 0 | H7: =IF(SUMPRODUCT(('alle Dateien'!B:B=Bohrungen!B7)*('alle Dateien'!D:D="las"))>0,1,0) -> 0 | I7: =IF(SUMPRODUCT(('alle Dateien'!B:B=Bohrungen!B7)*('alle Dateien'!D:D="db"))>0,1,0) -> 0 | J7: =IF(SUMPRODUCT(('alle Dateien'!B:B=Bohrungen!B7)*('alle Dateien'!D:D="rhistory"))>0,1,0) -> 0 | K7: =IF(SUMPRODUCT(('alle Dateien'!B:B=Bohrungen!B7)*('alle Dateien'!D:D="mdb"))>0,1,0) -> 0 | L7: =IF(SUMPRODUCT(('alle Dateien'!B:B=Bohrungen!B7)*('alle Dateien'!D:D="xml"))>0,1,0) -> 0 | M7: =IF(SUMPRODUCT(('alle Dateien'!B:B=Bohrungen!B7)*('alle Dateien'!D:D="jpg"))>0,1,0) -> 0 | N7: =IF(SUMPRODUCT(('alle Dateien'!B:B=Bohrungen!B7)*('alle Dateien'!D:D="png"))>0,1,0) -> 0 | O7: =IF(SUMPRODUCT(('alle Dateien'!B:B=Bohrungen!B7)*('alle Dateien'!D:D="xls"))>0,1,0) -> 0 | P7: =IF(SUMPRODUCT(('alle Dateien'!B:B=Bohrungen!B7)*('alle Dateien'!D:D="txt"))>0,1,0) -> 0 | Q7: =IF(SUMPRODUCT(('alle Dateien'!B:B=Bohrungen!B7)*('alle Dateien'!D:D="ZIP oder R"))>0,1,0) -> 0 | R7: =IF(SUMPRODUCT(('alle Dateien'!B:B=Bohrungen!B7)*('alle Dateien'!D:D="tsf"))>0,1,0) -> 0 | S7: =IF(SUMPRODUCT(('alle Dateien'!B:B=Bohrungen!B7)*('alle Dateien'!D:D="sch"))>0,1,0) -> 0 | U7: =CONCATENATE(C7,D7,E7,F7,G7,H7,I7,J7,K7,L7,M7,N7,O7,P7,Q7,R7,S7,) -> 10000000000000000 | V7: =VLOOKUP(U7,Kategorie!B:C,2,FALSE) -> pdf
A8: 7 | B8: Allmenhausen_35_1969 | C8: =IF(SUMPRODUCT(('alle Dateien'!B:B=Bohrungen!B8)*('alle Dateien'!D:D="pdf"))>0,1,0) -> 1 | D8: =IF(SUMPRODUCT(('alle Dateien'!B:B=Bohrungen!B8)*('alle Dateien'!D:D="tif"))>0,1,0) -> 1 | E8: =IF(SUMPRODUCT(('alle Dateien'!B:B=Bohrungen!B8)*('alle Dateien'!D:D="sdg"))>0,1,0) -> 1 | F8: =IF(SUMPRODUCT(('alle Dateien'!B:B=Bohrungen!B8)*('alle Dateien'!D:D="xlsx"))>0,1,0) -> 1 | G8: =IF(SUMPRODUCT(('alle Dateien'!B:B=Bohrungen!B8)*('alle Dateien'!D:D="docx"))>0,1,0) -> 1 | H8: =IF(SUMPRODUCT(('alle Dateien'!B:B=Bohrungen!B8)*('alle Dateien'!D:D="las"))>0,1,0) -> 1 | I8: =IF(SUMPRODUCT(('alle Dateien'!B:B=Bohrungen!B8)*('alle Dateien'!D:D="db"))>0,1,0) -> 1 | J8: =IF(SUMPRODUCT(('alle Dateien'!B:B=Bohrungen!B8)*('alle Dateien'!D:D="rhistory"))>0,1,0) -> 0 | K8: =IF(SUMPRODUCT(('alle Dateien'!B:B=Bohrungen!B8)*('alle Dateien'!D:D="mdb"))>0,1,0) -> 0 | L8: =IF(SUMPRODUCT(('alle Dateien'!B:B=Bohrungen!B8)*('alle Dateien'!D:D="xml"))>0,1,0) -> 0 | M8: =IF(SUMPRODUCT(('alle Dateien'!B:B=Bohrungen!B8)*('alle Dateien'!D:D="jpg"))>0,1,0) -> 0 | N8: =IF(SUMPRODUCT(('alle Dateien'!B:B=Bohrungen!B8)*('alle Dateien'!D:D="png"))>0,1,0) -> 0 | O8: =IF(SUMPRODUCT(('alle Dateien'!B:B=Bohrungen!B8)*('alle Dateien'!D:D="xls"))>0,1,0) -> 0 | P8: =IF(SUMPRODUCT(('alle Dateien'!B:B=Bohrungen!B8)*('alle Dateien'!D:D="txt"))>0,1,0) -> 0 | Q8: =IF(SUMPRODUCT(('alle Dateien'!B:B=Bohrungen!B8)*('alle Dateien'!D:D="ZIP oder R"))>0,1,0) -> 0 | R8: =IF(SUMPRODUCT(('alle Dateien'!B:B=Bohrungen!B8)*('alle Dateien'!D:D="tsf"))>0,1,0) -> 0 | S8: =IF(SUMPRODUCT(('alle Dateien'!B:B=Bohrungen!B8)*('alle Dateien'!D:D="sch"))>0,1,0) -> 0 | U8: =CONCATENATE(C8,D8,E8,F8,G8,H8,I8,J8,K8,L8,M8,N8,O8,P8,Q8,R8,S8,) -> 11111110000000000 | V8: =VLOOKUP(U8,Kategorie!B:C,2,FALSE) -> pdf/ tif/ sdg/ xlsx/ docx/ las/ db
A9: 8 | B9: Allmenhausen_4_1959 | C9: =IF(SUMPRODUCT(('alle Dateien'!B:B=Bohrungen!B9)*('alle Dateien'!D:D="pdf"))>0,1,0) -> 1 | D9: =IF(SUMPRODUCT(('alle Dateien'!B:B=Bohrungen!B9)*('alle Dateien'!D:D="tif"))>0,1,0) -> 0 | E9: =IF(SUMPRODUCT(('alle Dateien'!B:B=Bohrungen!B9)*('alle Dateien'!D:D="sdg"))>0,1,0) -> 0 | F9: =IF(SUMPRODUCT(('alle Dateien'!B:B=Bohrungen!B9)*('alle Dateien'!D:D="xlsx"))>0,1,0) -> 0 | G9: =IF(SUMPRODUCT(('alle Dateien'!B:B=Bohrungen!B9)*('alle Dateien'!D:D="docx"))>0,1,0) -> 0 | H9: =IF(SUMPRODUCT(('alle Dateien'!B:B=Bohrungen!B9)*('alle Dateien'!D:D="las"))>0,1,0) -> 0 | I9: =IF(SUMPRODUCT(('alle Dateien'!B:B=Bohrungen!B9)*('alle Dateien'!D:D="db"))>0,1,0) -> 0 | J9: =IF(SUMPRODUCT(('alle Dateien'!B:B=Bohrungen!B9)*('alle Dateien'!D:D="rhistory"))>0,1,0) -> 0 | K9: =IF(SUMPRODUCT(('alle Dateien'!B:B=Bohrungen!B9)*('alle Dateien'!D:D="mdb"))>0,1,0) -> 0 | L9: =IF(SUMPRODUCT(('alle Dateien'!B:B=Bohrungen!B9)*('alle Dateien'!D:D="xml"))>0,1,0) -> 0 | M9: =IF(SUMPRODUCT(('alle Dateien'!B:B=Bohrungen!B9)*('alle Dateien'!D:D="jpg"))>0,1,0) -> 0 | N9: =IF(SUMPRODUCT(('alle Dateien'!B:B=Bohrungen!B9)*('alle Dateien'!D:D="png"))>0,1,0) -> 0 | O9: =IF(SUMPRODUCT(('alle Dateien'!B:B=Bohrungen!B9)*('alle Dateien'!D:D="xls"))>0,1,0) -> 0 | P9: =IF(SUMPRODUCT(('alle Dateien'!B:B=Bohrungen!B9)*('alle Dateien'!D:D="txt"))>0,1,0) -> 0 | Q9: =IF(SUMPRODUCT(('alle Dateien'!B:B=Bohrungen!B9)*('alle Dateien'!D:D="ZIP oder R"))>0,1,0) -> 0 | R9: =IF(SUMPRODUCT(('alle Dateien'!B:B=Bohrungen!B9)*('alle Dateien'!D:D="tsf"))>0,1,0) -> 0 | S9: =IF(SUMPRODUCT(('alle Dateien'!B:B=Bohrungen!B9)*('alle Dateien'!D:D="sch"))>0,1,0) -> 0 | U9: =CONCATENATE(C9,D9,E9,F9,G9,H9,I9,J9,K9,L9,M9,N9,O9,P9,Q9,R9,S9,) -> 10000000000000000 | V9: =VLOOKUP(U9,Kategorie!B:C,2,FALSE) -> pdf
A10: 9 | B10: Allmenhausen_5_1962 | C10: =IF(SUMPRODUCT(('alle Dateien'!B:B=Bohrungen!B10)*('alle Dateien'!D:D="pdf"))>0,1,0) -> 1 | D10: =IF(SUMPRODUCT(('alle Dateien'!B:B=Bohrungen!B10)*('alle Dateien'!D:D="tif"))>0,1,0) -> 0 | E10: =IF(SUMPRODUCT(('alle Dateien'!B:B=Bohrungen!B10)*('alle Dateien'!D:D="sdg"))>0,1,0) -> 1 | F10: =IF(SUMPRODUCT(('alle Dateien'!B:B=Bohrungen!B10)*('alle Dateien'!D:D="xlsx"))>0,1,0) -> 1 | G10: =IF(SUMPRODUCT(('alle Dateien'!B:B=Bohrungen!B10)*('alle Dateien'!D:D="docx"))>0,1,0) -> 0 | H10: =IF(SUMPRODUCT(('alle Dateien'!B:B=Bohrungen!B10)*('alle Dateien'!D:D="las"))>0,1,0) -> 1 | I10: =IF(SUMPRODUCT(('alle Dateien'!B:B=Bohrungen!B10)*('alle Dateien'!D:D="db"))>0,1,0) -> 0 | J10: =IF(SUMPRODUCT(('alle Dateien'!B:B=Bohrungen!B10)*('alle Dateien'!D:D="rhistory"))>0,1,0) -> 1 | K10: =IF(SUMPRODUCT(('alle Dateien'!B:B=Bohrungen!B10)*('alle Dateien'!D:D="mdb"))>0,1,0) -> 0 | L10: =IF(SUMPRODUCT(('alle Dateien'!B:B=Bohrungen!B10)*('alle Dateien'!D:D="xml"))>0,1,0) -> 0 | M10: =IF(SUMPRODUCT(('alle Dateien'!B:B=Bohrungen!B10)*('alle Dateien'!D:D="jpg"))>0,1,0) -> 0 | N10: =IF(SUMPRODUCT(('alle Dateien'!B:B=Bohrungen!B10)*('alle Dateien'!D:D="png"))>0,1,0) -> 0 | O10: =IF(SUMPRODUCT(('alle Dateien'!B:B=Bohrungen!B10)*('alle Dateien'!D:D="xls"))>0,1,0) -> 0 | P10: =IF(SUMPRODUCT(('alle Dateien'!B:B=Bohrungen!B10)*('alle Dateien'!D:D="txt"))>0,1,0) -> 0 | Q10: =IF(SUMPRODUCT(('alle Dateien'!B:B=Bohrungen!B10)*('alle Dateien'!D:D="ZIP oder R"))>0,1,0) -> 0 | R10: =IF(SUMPRODUCT(('alle Dateien'!B:B=Bohrungen!B10)*('alle Dateien'!D:D="tsf"))>0,1,0) -> 0 | S10: =IF(SUMPRODUCT(('alle Dateien'!B:B=Bohrungen!B10)*('alle Dateien'!D:D="sch"))>0,1,0) -> 0 | U10: =CONCATENATE(C10,D10,E10,F10,G10,H10,I10,J10,K10,L10,M10,N10,O10,P10,Q10,R10,S10,) -> 10110101000000000 | V10: =VLOOKUP(U10,Kategorie!B:C,2,FALSE) -> pdf/ sdg/ xlsx/ las/ rhistory
A11: 10 | B11: Allmenhausen_6_1960 | C11: =IF(SUMPRODUCT(('alle Dateien'!B:B=Bohrungen!B11)*('alle Dateien'!D:D="pdf"))>0,1,0) -> 1 | D11: =IF(SUMPRODUCT(('alle Dateien'!B:B=Bohrungen!B11)*('alle Dateien'!D:D="tif"))>0,1,0) -> 0 | E11: =IF(SUMPRODUCT(('alle Dateien'!B:B=Bohrungen!B11)*('alle Dateien'!D:D="sdg"))>0,1,0) -> 0 | F11: =IF(SUMPRODUCT(('alle Dateien'!B:B=Bohrungen!B11)*('alle Dateien'!D:D="xlsx"))>0,1,0) -> 0 | G11: =IF(SUMPRODUCT(('alle Dateien'!B:B=Bohrungen!B11)*('alle Dateien'!D:D="docx"))>0,1,0) -> 0 | H11: =IF(SUMPRODUCT(('alle Dateien'!B:B=Bohrungen!B11)*('alle Dateien'!D:D="las"))>0,1,0) -> 0 | I11: =IF(SUMPRODUCT(('alle Dateien'!B:B=Bohrungen!B11)*('alle Dateien'!D:D="db"))>0,1,0) -> 0 | J11: =IF(SUMPRODUCT(('alle Dateien'!B:B=Bohrungen!B11)*('alle Dateien'!D:D="rhistory"))>0,1,0) -> 0 | K11: =IF(SUMPRODUCT(('alle Dateien'!B:B=Bohrungen!B11)*('alle Dateien'!D:D="mdb"))>0,1,0) -> 0 | L11: =IF(SUMPRODUCT(('alle Dateien'!B:B=Bohrungen!B11)*('alle Dateien'!D:D="xml"))>0,1,0) -> 0 | M11: =IF(SUMPRODUCT(('alle Dateien'!B:B=Bohrungen!B11)*('alle Dateien'!D:D="jpg"))>0,1,0) -> 0 | N11: =IF(SUMPRODUCT(('alle Dateien'!B:B=Bohrungen!B11)*('alle Dateien'!D:D="png"))>0,1,0) -> 0 | O11: =IF(SUMPRODUCT(('alle Dateien'!B:B=Bohrungen!B11)*('alle Dateien'!D:D="xls"))>0,1,0) -> 0 | P11: =IF(SUMPRODUCT(('alle Dateien'!B:B=Bohrungen!B11)*('alle Dateien'!D:D="txt"))>0,1,0) -> 0 | Q11: =IF(SUMPRODUCT(('alle Dateien'!B:B=Bohrungen!B11)*('alle Dateien'!D:D="ZIP oder R"))>0,1,0) -> 0 | R11: =IF(SUMPRODUCT(('alle Dateien'!B:B=Bohrungen!B11)*('alle Dateien'!D:D="tsf"))>0,1,0) -> 0 | S11: =IF(SUMPRODUCT(('alle Dateien'!B:B=Bohrungen!B11)*('alle Dateien'!D:D="sch"))>0,1,0) -> 0 | U11: =CONCATENATE(C11,D11,E11,F11,G11,H11,I11,J11,K11,L11,M11,N11,O11,P11,Q11,R11,S11,) -> 10000000000000000 | V11: =VLOOKUP(U11,Kategorie!B:C,2,FALSE) -> pdf
A12: 11 | B12: Allmenhausen_8_1960 | C12: =IF(SUMPRODUCT(('alle Dateien'!B:B=Bohrungen!B12)*('alle Dateien'!D:D="pdf"))>0,1,0) -> 1 | D12: =IF(SUMPRODUCT(('alle Dateien'!B:B=Bohrungen!B12)*('alle Dateien'!D:D="tif"))>0,1,0) -> 0 | E12: =IF(SUMPRODUCT(('alle Dateien'!B:B=Bohrungen!B12)*('alle Dateien'!D:D="sdg"))>0,1,0) -> 0 | F12: =IF(SUMPRODUCT(('alle Dateien'!B:B=Bohrungen!B12)*('alle Dateien'!D:D="xlsx"))>0,1,0) -> 0 | G12: =IF(SUMPRODUCT(('alle Dateien'!B:B=Bohrungen!B12)*('alle Dateien'!D:D="docx"))>0,1,0) -> 0 | H12: =IF(SUMPRODUCT(('alle Dateien'!B:B=Bohrungen!B12)*('alle Dateien'!D:D="las"))>0,1,0) -> 0 | I12: =IF(SUMPRODUCT(('alle Dateien'!B:B=Bohrungen!B12)*('alle Dateien'!D:D="db"))>0,1,0) -> 0 | J12: =IF(SUMPRODUCT(('alle Dateien'!B:B=Bohrungen!B12)*('alle Dateien'!D:D="rhistory"))>0,1,0) -> 0 | K12: =IF(SUMPRODUCT(('alle Dateien'!B:B=Bohrungen!B12)*('alle Dateien'!D:D="mdb"))>0,1,0) -> 0 | L12: =IF(SUMPRODUCT(('alle Dateien'!B:B=Bohrungen!B12)*('alle Dateien'!D:D="xml"))>0,1,0) -> 0 | M12: =IF(SUMPRODUCT(('alle Dateien'!B:B=Bohrungen!B12)*('alle Dateien'!D:D="jpg"))>0,1,0) -> 0 | N12: =IF(SUMPRODUCT(('alle Dateien'!B:B=Bohrungen!B12)*('alle Dateien'!D:D="png"))>0,1,0) -> 0 | O12: =IF(SUMPRODUCT(('alle Dateien'!B:B=Bohrungen!B12)*('alle Dateien'!D:D="xls"))>0,1,0) -> 0 | P12: =IF(SUMPRODUCT(('alle Dateien'!B:B=Bohrungen!B12)*('alle Dateien'!D:D="txt"))>0,1,0) -> 0 | Q12: =IF(SUMPRODUCT(('alle Dateien'!B:B=Bohrungen!B12)*('alle Dateien'!D:D="ZIP oder R"))>0,1,0) -> 0 | R12: =IF(SUMPRODUCT(('alle Dateien'!B:B=Bohrungen!B12)*('alle Dateien'!D:D="tsf"))>0,1,0) -> 0 | S12: =IF(SUMPRODUCT(('alle Dateien'!B:B=Bohrungen!B12)*('alle Dateien'!D:D="sch"))>0,1,0) -> 0 | U12: =CONCATENATE(C12,D12,E12,F12,G12,H12,I12,J12,K12,L12,M12,N12,O12,P12,Q12,R12,S12,) -> 10000000000000000 | V12: =VLOOKUP(U12,Kategorie!B:C,2,FALSE) -> pdf
A13: 12 | B13: Altengottern_102E_1958 | C13: =IF(SUMPRODUCT(('alle Dateien'!B:B=Bohrungen!B13)*('alle Dateien'!D:D="pdf"))>0,1,0) -> 0 | D13: =IF(SUMPRODUCT(('alle Dateien'!B:B=Bohrungen!B13)*('alle Dateien'!D:D="tif"))>0,1,0) -> 0 | E13: =IF(SUMPRODUCT(('alle Dateien'!B:B=Bohrungen!B13)*('alle Dateien'!D:D="sdg"))>0,1,0) -> 1 | F13: =IF(SUMPRODUCT(('alle Dateien'!B:B=Bohrungen!B13)*('alle Dateien'!D:D="xlsx"))>0,1,0) -> 1 | G13: =IF(SUMPRODUCT(('alle Dateien'!B:B=Bohrungen!B13)*('alle Dateien'!D:D="docx"))>0,1,0) -> 0 | H13: =IF(SUMPRODUCT(('alle Dateien'!B:B=Bohrungen!B13)*('alle Dateien'!D:D="las"))>0,1,0) -> 1 | I13: =IF(SUMPRODUCT(('alle Dateien'!B:B=Bohrungen!B13)*('alle Dateien'!D:D="db"))>0,1,0) -> 0 | J13: =IF(SUMPRODUCT(('alle Dateien'!B:B=Bohrungen!B13)*('alle Dateien'!D:D="rhistory"))>0,1,0) -> 0 | K13: =IF(SUMPRODUCT(('alle Dateien'!B:B=Bohrungen!B13)*('alle Dateien'!D:D="mdb"))>0,1,0) -> 0 | L13: =IF(SUMPRODUCT(('alle Dateien'!B:B=Bohrungen!B13)*('alle Dateien'!D:D="xml"))>0,1,0) -> 0 | M13: =IF(SUMPRODUCT(('alle Dateien'!B:B=Bohrungen!B13)*('alle Dateien'!D:D="jpg"))>0,1,0) -> 0 | N13: =IF(SUMPRODUCT(('alle Dateien'!B:B=Bohrungen!B13)*('alle Dateien'!D:D="png"))>0,1,0) -> 0 | O13: =IF(SUMPRODUCT(('alle Dateien'!B:B=Bohrungen!B13)*('alle Dateien'!D:D="xls"))>0,1,0) -> 0 | P13: =IF(SUMPRODUCT(('alle Dateien'!B:B=Bohrungen!B13)*('alle Dateien'!D:D="txt"))>0,1,0) -> 0 | Q13: =IF(SUMPRODUCT(('alle Dateien'!B:B=Bohrungen!B13)*('alle Dateien'!D:D="ZIP oder R"))>0,1,0) -> 0 | R13: =IF(SUMPRODUCT(('alle Dateien'!B:B=Bohrungen!B13)*('alle Dateien'!D:D="tsf"))>0,1,0) -> 0 | S13: =IF(SUMPRODUCT(('alle Dateien'!B:B=Bohrungen!B13)*('alle Dateien'!D:D="sch"))>0,1,0) -> 0 | U13: =CONCATENATE(C13,D13,E13,F13,G13,H13,I13,J13,K13,L13,M13,N13,O13,P13,Q13,R13,S13,) -> 00110100000000000 | V13: =VLOOKUP(U13,Kategorie!B:C,2,FALSE) -> sdg/ xlsx/ las
... A188: 187 | B188: Zoppoten_3_1964 | C188: =IF(SUMPRODUCT(('alle Dateien'!B:B=Bohrungen!B188)*('alle Dateien'!D:D="pdf"))>0,1,0) -> 0 | D188: =IF(SUMPRODUCT(('alle Dateien'!B:B=Bohrungen!B188)*('alle Dateien'!D:D="tif"))>0,1,0) -> 0 | E188: =IF(SUMPRODUCT(('alle Dateien'!B:B=Bohrungen!B188)*('alle Dateien'!D:D="sdg"))>0,1,0) -> 1 | F188: =IF(SUMPRODUCT(('alle Dateien'!B:B=Bohrungen!B188)*('alle Dateien'!D:D="xlsx"))>0,1,0) -> 1 | G188: =IF(SUMPRODUCT(('alle Dateien'!B:B=Bohrungen!B188)*('alle Dateien'!D:D="docx"))>0,1,0) -> 0 | H188: =IF(SUMPRODUCT(('alle Dateien'!B:B=Bohrungen!B188)*('alle Dateien'!D:D="las"))>0,1,0) -> 1 | I188: =IF(SUMPRODUCT(('alle Dateien'!B:B=Bohrungen!B188)*('alle Dateien'!D:D="db"))>0,1,0) -> 0 | J188: =IF(SUMPRODUCT(('alle Dateien'!B:B=Bohrungen!B188)*('alle Dateien'!D:D="rhistory"))>0,1,0) -> 0 | K188: =IF(SUMPRODUCT(('alle Dateien'!B:B=Bohrungen!B188)*('alle Dateien'!D:D="mdb"))>0,1,0) -> 0 | L188: =IF(SUMPRODUCT(('alle Dateien'!B:B=Bohrungen!B188)*('alle Dateien'!D:D="xml"))>0,1,0) -> 0 | M188: =IF(SUMPRODUCT(('alle Dateien'!B:B=Bohrungen!B188)*('alle Dateien'!D:D="jpg"))>0,1,0) -> 0 | N188: =IF(SUMPRODUCT(('alle Dateien'!B:B=Bohrungen!B188)*('alle Dateien'!D:D="png"))>0,1,0) -> 0 | O188: =IF(SUMPRODUCT(('alle Dateien'!B:B=Bohrungen!B188)*('alle Dateien'!D:D="xls"))>0,1,0) -> 0 | P188: =IF(SUMPRODUCT(('alle Dateien'!B:B=Bohrungen!B188)*('alle Dateien'!D:D="txt"))>0,1,0) -> 0 | Q188: =IF(SUMPRODUCT(('alle Dateien'!B:B=Bohrungen!B188)*('alle Dateien'!D:D="ZIP oder R"))>0,1,0) -> 0 | R188: =IF(SUMPRODUCT(('alle Dateien'!B:B=Bohrungen!B188)*('alle Dateien'!D:D="tsf"))>0,1,0) -> 0 | S188: =IF(SUMPRODUCT(('alle Dateien'!B:B=Bohrungen!B188)*('alle Dateien'!D:D="sch"))>0,1,0) -> 0 | U188: =CONCATENATE(C188,D188,E188,F188,G188,H188,I188,J188,K188,L188,M188,N188,O188,P188,Q188,R188,S188,) -> 00110100000000000 | V188: =VLOOKUP(U188,Kategorie!B:C,2,FALSE) -> sdg/ xlsx/ las

Sheet Geo_Koordinaten
A1: ID | B1: Bohrungen | C1: E_EPSG31468 | D1: N_EPSG31468
A2: 1 | B2: Allmenhausen_10_1960 | C2: 4415490 | D2: 5675848.4
A3: 2 | B3: Allmenhausen_11_1960 | C3: 4407839.3 | D3: 5679498.9
A4: 3 | B4: Allmenhausen_2_1959 | C4: 4411971.7 | D4: 5676242.2
A5: 4 | B5: Allmenhausen_32_1968 | C5: 4410119.8 | D5: 5677194.8
A6: 5 | B6: Allmenhausen_33_1968 | C6: 4410449.1 | D6: 5677385.9
A7: 6 | B7: Allmenhausen_34_1969 | C7: 4410942.4 | D7: 5677743
A8: 7 | B8: Allmenhausen_35_1969 | C8: 4410185.4 | D8: 5677862.9
A9: 8 | B9: Allmenhausen_4_1959 | C9: 4411316.2 | D9: 5680498.3
A10: 9 | B10: Allmenhausen_5_1962 | C10: 4414062.1 | D10: 5674935.2
A11: 10 | B11: Allmenhausen_6_1960 | C11: 4412526.7 | D11: 5677148.5
A12: 11 | B12: Allmenhausen_8_1960 | C12: 4410370.9 | D12: 5678783.6
A13: 12 | B13: Altengottern_102E_1958 | C13: 4399687.1 | D13: 5673102.7
... A73: 72 | B73: Hainich_Hallungen_1_1962 | C73: 4381905 | D73: 5668533.9
A74: 73 | B74: Hainich_Region
A75: 74 | B75: Hainleite_1_1963 | C75: 4425463.9 | D75: 5689057.9
A76: 75 | B76: Haussömmern_1_1970 | C76: 4419570.6 | D76: 5670916.6
A77: 76 | B77: Hohenwart_3_1967 | C77: 4364949.2 | D77: 5627334.9
A78: 77 | B78: Holzsußra_2_1970 | C78: 4407898 | D78: 5685198.2
A79: 78 | B79: Holzthaleben_2_1969 | C79: 4402868.7 | D79: 5689303.1
A80: 79 | B80: Holzthaleben_3_1970 | C80: 4403351.9 | D80: 5690008.8
A81: 80 | B81: Holzthaleben_4_1970 | C81: 4404306.4 | D81: 5690367
A82: 81 | B82: Holzthaleben_5_1971 | C82: 4406226.6 | D82: 5691376.4
A83: 82 | B83: Ilfeld_1_1991 | C83: 4416254.2 | D83: 5716137
A84: 83 | B84: Jena_Z_103_1963 | C84: 4458846.6 | D84: 5656519.4
A85: 84 | B85: Jena_Z_104_1962 | C85: 4476812.6 | D85: 5657389.5
A86: 85 | B86: Kalbsrieth_5_1986 | C86: 4455281.3 | D86: 5690669.8
... A117: 116 | B117: Kuellstedt_2_1966 | C117: 4376471.4 | D117: 5684737.6
A118: 117 | B118: Küllstedt_Region
A119: 118 | B119: Langensalza_109_1959 | C119: 4411504.3 | D119: 5665712.8
